Workbook

Sheet Analysis
A1: date | B1: species | C1: birdid | D1: filenum | E1: type | F1: lmax | G1: difference used | H1: use | I1: note
A2: 43768 | B2: hago | C2: 101 | D2: 48 | E2: dc | F2: 573 | G2: 0
A3: 43768 | B3: hago | C3: 101 | D3: 17 | E3: lws | F3: 576 | G3: 1
A4: 43768 | B4: hago | C4: 101 | D4: 109 | E4: lws | F4: 568 | G4: 1
A5: 43768 | B5: hago | C5: 101 | D5: 123 | E5: lws | F5: 560 | G5: 1 | I5: with R-Type associated
A6: 43768 | B6: hago | C6: 101 | D6: 14 | E6: mws | F6: 516 | G6: 1
A7: 43768 | B7: hago | C7: 101 | D7: 51 | E7: mws | F7: 506 | G7: 1
A8: 43768 | B8: hago | C8: 101 | D8: 67 | E8: mws | F8: 506 | G8: 1
A9: 43768 | B9: hago | C9: 101 | D9: 69 | E9: mws | F9: 505 | G9: 1
A10: 43768 | B10: hago | C10: 101 | D10: 74 | E10: mws | F10: 502 | G10: 1
A11: 43768 | B11: hago | C11: 101 | D11: 102 | E11: mws | F11: 510 | G11: 1
A12: 43768 | B12: hago | C12: 101 | D12: 138 | E12: mws | F12: 504 | G12: 1
A13: 43768 | B13: hago | C13: 101 | D13: 197 | E13: mws | F13: 496 | G13: 1
A14: 43768 | B14: hago | C14: 101 | D14: 208 | E14: mws | F14: 503 | G14: 1
A15: 43768 | B15: hago | C15: 101 | D15: 3 | E15: rod | F15: 504 | G15: 1
A16: 43768 | B16: hago | C16: 101 | D16: 12 | E16: rod | F16: 503 | G16: 1
A17: 43768 | B17: hago | C17: 101 | D17: 27 | E17: rod | F17: 503 | G17: 1
... A23: 43768 | B23: hago | C23: 101 | D23: 195 | E23: rod | F23: 503 | G23: 1
A24: 43768 | B24: hago | C24: 101 | D24: 46 | E24: sws | F24: 487 | G24: 1 | H24: ??? | I24: mws?
A25: 43768 | B25: hago | C25: 101 | D25: 117 | E25: sws | F25: 477 | G25: 1
A26: 43768 | B26: hago | C26: 101 | D26: 126 | E26: sws | F26: 484 | G26: 1
A27: 43768 | B27: hago | C27: 101 | D27: 151 | E27: sws | F27: 483 | G27: 1
A28: 43768 | B28: hago | C28: 101 | D28: 160 | E28: sws | F28: 485 | G28: 1
A29: 43768 | B29: hago | C29: 101 | D29: 206 | E29: sws | F29: 482 | G29: 1
A30: 43768 | B30: hago | C30: 101 | D30: 25 | E30: vs | F30: 410 | G30: 1
A31: 43768 | B31: hago | C31: 101 | D31: 87 | E31: vs | F31: 414 | G31: 1
A32: 43768 | B32: hago | C32: 101 | D32: 113 | E32: vs | F32: 407 | G32: 1
A33: 43768 | B33: hago | C33: 101 | D33: 141 | E33: vs | F33: 422 | G33: 1 | I33: rot

Sheet Averages
A1: HAGO101
A2: File # | B2: RH1 Lambda Max | D2: File # | E2: VS Lambda Max | G2: File # | H2: SWS Lambda Max | J2: File # | K2: MWS Lambda Max | M2: File # | N2: LWS Lambda Max | P2: File # | Q2: DC Lambda Max
A3: =Analysis!D15 -> 3 | B3: =Analysis!F15 -> 504 | D3: =Analysis!D30 -> 25 | E3: =Analysis!F30 -> 410 | G3: =Analysis!D24 -> 46 | H3: =Analysis!F24 -> 487 | J3: =Analysis!D6 -> 14 | K3: =Analysis!F6 -> 516 | M3: =Analysis!D3 -> 17 | N3: =Analysis!F3 -> 576 | P3: =Analysis!D2 -> 48 | Q3: =Analysis!F2 -> 573
A4: =Analysis!D16 -> 12 | B4: =Analysis!F16 -> 503 | D4: =Analysis!D31 -> 87 | E4: =Analysis!F31 -> 414 | G4: =Analysis!D25 -> 117 | H4: =Analysis!F25 -> 477 | J4: =Analysis!D7 -> 51 | K4: =Analysis!F7 -> 506 | M4: =Analysis!D4 -> 109 | N4: =Analysis!F4 -> 568
A5: =Analysis!D17 -> 27 | B5: =Analysis!F17 -> 503 | D5: =Analysis!D32 -> 113 | E5: =Analysis!F32 -> 407 | G5: =Analysis!D26 -> 126 | H5: =Analysis!F26 -> 484 | J5: =Analysis!D8 -> 67 | K5: =Analysis!F8 -> 506 | M5: =Analysis!D5 -> 123 | N5: =Analysis!F5 -> 560
A6: =Analysis!D18 -> 63 | B6: =Analysis!F18 -> 503 | D6: =Analysis!D33 -> 141 | E6: =Analysis!F33 -> 422 | G6: =Analysis!D27 -> 151 | H6: =Analysis!F27 -> 483 | J6: =Analysis!D9 -> 69 | K6: =Analysis!F9 -> 505
A7: =Analysis!D19 -> 82 | B7: =Analysis!F19 -> 506 | G7: =Analysis!D28 -> 160 | H7: =Analysis!F28 -> 485 | J7: =Analysis!D10 -> 74 | K7: =Analysis!F10 -> 502
A8: =Analysis!D20 -> 100 | B8: =Analysis!F20 -> 502 | G8: =Analysis!D29 -> 206 | H8: =Analysis!F29 -> 482 | J8: =Analysis!D11 -> 102 | K8: =Analysis!F11 -> 510
A9: =Analysis!D21 -> 136 | B9: =Analysis!F21 -> 504 | J9: =Analysis!D12 -> 138 | K9: =Analysis!F12 -> 504
A10: =Analysis!D22 -> 184 | B10: =Analysis!F22 -> 503 | J10: =Analysis!D13 -> 197 | K10: =Analysis!F13 -> 496
A11: =Analysis!D23 -> 195 | B11: =Analysis!F23 -> 503 | J11: =Analysis!D14 -> 208 | K11: =Analysis!F14 -> 503
A17: AVG | B17: =AVERAGE(B3:B15) -> 503.44444 | D17: AVG | E17: =AVERAGE(E3:E7) -> 413.25 | G17: AVG | H17: =AVERAGE(H3:H12) -> 483 | J17: AVG | K17: =AVERAGE(K3:K15) -> 505.33333 | M17: AVG | N17: =AVERAGE(N3:N12) -> 568 | P17: AVG | Q17: =AVERAGE(Q3:Q4) -> 573
A18: SD | B18: =STDEV(B3:B15) -> 1.1303883 | D18: SD | E18: =STDEV(E3:E7) -> 6.5 | G18: SD | H18: =STDEV(H3:H12) -> 3.4058773 | J18: SD | K18: =STDEV(K3:K15) -> 5.5 | M18: SD | N18: =STDEV(N3:N12) -> 8 | P18: SD | Q18: 0
A19: SE | B19: =B18/SQRT(COUNT(B3:B15)) -> 0.37679611 | D19: SE | E19: =E18/SQRT(COUNT(E3:E7)) -> 3.25 | G19: SE | H19: =H18/SQRT(COUNT(H3:H12)) -> 1.3904436 | J19: SE | K19: =K18/SQRT(COUNT(K3:K15)) -> 1.8333333 | M19: SE | N19: =N18/SQRT(COUNT(N3:N12)) -> 4.6188022 | P19: SE | Q19: 0
A20: N | B20: =COUNT(B3:B15) -> 9 | E20: =COUNT(E3:E7) -> 4 | H20: =COUNT(H3:H12) -> 6 | K20: =COUNT(K3:K15) -> 9 | N20: =COUNT(N3:N12) -> 3 | Q20: =COUNT(Q3:Q4) -> 1

Sheet Raw Data
A1: wl | B1: 2019 Oct 30 - 3.XLS | C1: 2019 Oct 30 - 4.XLS | D1: 2019 Oct 30 - 12.XLS | E1: 2019 Oct 30 - 13.XLS | F1: 2019 Oct 30 - 14.XLS | G1: 2019 Oct 30 - 15.XLS | H1: 2019 Oct 30 - 17.XLS | I1: 2019 Oct 30 - 19.XLS | J1: 2019 Oct 30 - 25.XLS | K1: 2019 Oct 30 - 26.XLS | L1: 2019 Oct 30 - 27.XLS | M1: 2019 Oct 30 - 28.XLS | N1: 2019 Oct 30 - 46.XLS | O1: 2019 Oct 30 - 47.XLS | P1: 2019 Oct 30 - 48.XLS | Q1: 2019 Oct 30 - 49.XLS | R1: 2019 Oct 30 - 51.XLS | S1: 2019 Oct 30 - 53.XLS | T1: 2019 Oct 30 - 63.XLS | U1: 2019 Oct 30 - 64.XLS | V1: 2019 Oct 31 - 67.XLS | W1: 2019 Oct 31 - 68.XLS | X1: 2019 Oct 31 - 69.XLS | Y1: 2019 Oct 31 - 70.XLS | Z1: 2019 Oct 31 - 74.XLS | AA1: 2019 Oct 31 - 75.XLS | AB1: 2019 Oct 31 - 82.XLS | AC1: 2019 Oct 31 - 83.XLS | AD1: 2019 Oct 31 - 87.XLS | AE1: 2019 Oct 31 - 89.XLS | AF1: 2019 Oct 31 - 100.XLS | AG1: 2019 Oct 31 - 101.XLS | AH1: 2019 Oct 31 - 102.XLS | AI1: 2019 Oct 31 - 103.XLS | AJ1: 2019 Oct 31 - 109.XLS | AK1: 2019 Oct 31 - 110.XLS | AL1: 2019 Oct 31 - 113.XLS | AM1: 2019 Oct 31 - 116.XLS | AN1: 2019 Oct 31 - 117.XLS | AO1: 2019 Oct 31 - 118.XLS | AP1: 2019 Oct 31 - 123.XLS | AQ1: 2019 Oct 31 - 124.XLS | AR1: 2019 Oct 31 - 126.XLS | AS1: 2019 Oct 31 - 128.XLS | AT1: 2019 Oct 31 - 136.XLS | AU1: 2019 Oct 31 - 137.XLS | AV1: 2019 Oct 31 - 138.XLS | AW1: 2019 Oct 31 - 140.XLS | AX1: 2019 Oct 31 - 141.XLS | AY1: 2019 Oct 31 - 144.XLS | AZ1: 2019 Oct 31 - 151.XLS | BA1: 2019 Oct 31 - 153.XLS | BB1: 2019 Oct 31 - 160.XLS | BC1: 2019 Oct 31 - 161.XLS | BD1: 2019 Oct 31 - 184.XLS | BE1: 2019 Oct 31 - 185.XLS | BF1: 2019 Oct 31 - 195.XLS | BG1: 2019 Oct 31 - 196.XLS | BH1: 2019 Oct 31 - 197.XLS | BI1: 2019 Oct 31 - 198.XLS | BJ1: 2019 Oct 31 - 206.XLS | BK1: 2019 Oct 31 - 207.XLS | BL1: 2019 Oct 31 - 208.XLS | BM1: 2019 Oct 31 - 209.XLS
A2: 350 | B2: 0.023 | C2: 0.049 | D2: 0.094 | E2: 0.063 | F2: -0.002 | G2: 0.045 | H2: 0.023 | I2: -0.055 | J2: 0 | K2: -0.018 | L2: -0.006 | M2: 0.08 | N2: 0.015 | O2: 0.008 | P2: 0.027 | Q2: 0.056 | R2: 0.079 | S2: 0.066 | T2: 0.052 | U2: 0.059 | V2: 0.011 | W2: -0.002 | X2: -0.008 | Y2: 0.074 | Z2: 0.014 | AA2: 0.016 | AB2: 0.076 | AC2: 0.126 | AD2: 0.034 | AE2: 0.033 | AF2: 0.024 | AG2: 0.065 | AH2: 0.059 | AI2: 0.057 | AJ2: 0.059 | AK2: 0.02 | AL2: 0.066 | AM2: 0.021 | AN2: 0.068 | AO2: 0.054 | AP2: -0.002 | AQ2: 0.005 | AR2: -0.009 | AS2: 0.008 | AT2: 0.002 | AU2: 0.077 | AV2: 0.064 | AW2: 0.076 | AX2: 0.001 | AY2: 0.003 | AZ2: 0.014 | BA2: 0.018 | BB2: 0.006 | BC2: 0.01 | BD2: 0.089 | BE2: 0.054 | BF2: 0.017 | BG2: 0.064 | BH2: 0.06 | BI2: 0.025 | BJ2: 0.002 | BK2: 0.007 | BL2: 0.033 | BM2: -0.001
A3: 351 | B3: 0.031 | C3: 0.051 | D3: 0.075 | E3: 0.069 | F3: 0.001 | G3: 0.03 | H3: 0.022 | I3: -0.061 | J3: 0.023 | K3: 0.004 | L3: 0.014 | M3: 0.092 | N3: 0.013 | O3: -0.006 | P3: 0.015 | Q3: 0.045 | R3: 0.06 | S3: 0.061 | T3: 0.053 | U3: 0.071 | V3: 0.011 | W3: -0.009 | X3: -0.001 | Y3: 0.079 | Z3: 0.019 | AA3: 0.014 | AB3: 0.076 | AC3: 0.115 | AD3: 0.005 | AE3: -0.001 | AF3: 0.036 | AG3: 0.064 | AH3: 0.04 | AI3: 0.05 | AJ3: 0.067 | AK3: 0.035 | AL3: 0.063 | AM3: 0.021 | AN3: 0.057 | AO3: 0.062 | AP3: 0.001 | AQ3: -0.002 | AR3: -0.031 | AS3: 0 | AT3: -0.005 | AU3: 0.073 | AV3: 0.061 | AW3: 0.069 | AX3: 0.008 | AY3: 0.011 | AZ3: 0 | BA3: 0.015 | BB3: 0.005 | BC3: 0.003 | BD3: 0.091 | BE3: 0.052 | BF3: 0.021 | BG3: 0.071 | BH3: 0.056 | BI3: 0.024 | BJ3: 0.01 | BK3: 0.022 | BL3: 0.036 | BM3: -0.001
A4: 352 | B4: 0.035 | C4: 0.051 | D4: 0.073 | E4: 0.065 | F4: 0.009 | G4: 0.03 | H4: 0.015 | I4: -0.067 | J4: 0.022 | K4: 0.006 | L4: 0.01 | M4: 0.093 | N4: 0.014 | O4: -0.001 | P4: 0.007 | Q4: 0.041 | R4: 0.049 | S4: 0.052 | T4: 0.039 | U4: 0.053 | V4: 0.009 | W4: -0.024 | X4: 0.013 | Y4: 0.083 | Z4: 0.02 | AA4: 0.016 | AB4: 0.079 | AC4: 0.108 | AD4: 0.006 | AE4: 0.009 | AF4: 0.038 | AG4: 0.058 | AH4: 0.038 | AI4: 0.056 | AJ4: 0.069 | AK4: 0.03 | AL4: 0.046 | AM4: 0.02 | AN4: 0.064 | AO4: 0.07 | AP4: -0.003 | AQ4: 0.007 | AR4: -0.027 | AS4: -0.007 | AT4: -0.001 | AU4: 0.071 | AV4: 0.065 | AW4: 0.07 | AX4: 0.001 | AY4: 0 | AZ4: -0.004 | BA4: 0.013 | BB4: 0.011 | BC4: 0.009 | BD4: 0.081 | BE4: 0.051 | BF4: 0.008 | BG4: 0.07 | BH4: 0.051 | BI4: 0.022 | BJ4: 0.011 | BK4: 0.015 | BL4: 0.034 | BM4: -0.002
A5: 353 | B5: 0.045 | C5: 0.058 | D5: 0.086 | E5: 0.074 | F5: 0.013 | G5: 0.048 | H5: 0.027 | I5: -0.068 | J5: 0.016 | K5: 0.004 | L5: 0.02 | M5: 0.095 | N5: 0.029 | O5: 0.009 | P5: 0.014 | Q5: 0.046 | R5: 0.059 | S5: 0.055 | T5: 0.024 | U5: 0.049 | V5: 0.012 | W5: -0.014 | X5: 0.006 | Y5: 0.084 | Z5: 0.019 | AA5: 0.021 | AB5: 0.068 | AC5: 0.104 | AD5: 0.008 | AE5: 0.008 | AF5: 0.035 | AG5: 0.067 | AH5: 0.04 | AI5: 0.061 | AJ5: 0.055 | AK5: 0.024 | AL5: 0.043 | AM5: 0.028 | AN5: 0.063 | AO5: 0.067 | AP5: 0.004 | AQ5: 0 | AR5: -0.018 | AS5: -0.006 | AT5: 0.004 | AU5: 0.083 | AV5: 0.064 | AW5: 0.061 | AX5: 0.008 | AY5: 0.006 | AZ5: 0.001 | BA5: 0.006 | BB5: 0.014 | BC5: 0.015 | BD5: 0.088 | BE5: 0.058 | BF5: 0.005 | BG5: 0.066 | BH5: 0.047 | BI5: 0.024 | BJ5: 0.02 | BK5: 0.015 | BL5: 0.039 | BM5: -0.003
A6: 354 | B6: 0.046 | C6: 0.057 | D6: 0.083 | E6: 0.074 | F6: 0.004 | G6: 0.027 | H6: 0.031 | I6: -0.065 | J6: 0.017 | K6: 0.007 | L6: 0.017 | M6: 0.095 | N6: 0.028 | O6: 0.015 | P6: 0.013 | Q6: 0.042 | R6: 0.051 | S6: 0.059 | T6: 0.022 | U6: 0.049 | V6: 0.016 | W6: 0.003 | X6: 0.011 | Y6: 0.083 | Z6: 0.012 | AA6: 0.017 | AB6: 0.067 | AC6: 0.106 | AD6: 0.003 | AE6: -0.007 | AF6: 0.049 | AG6: 0.078 | AH6: 0.046 | AI6: 0.06 | AJ6: 0.068 | AK6: 0.035 | AL6: 0.048 | AM6: 0.028 | AN6: 0.061 | AO6: 0.066 | AP6: 0.008 | AQ6: 0.008 | AR6: -0.009 | AS6: 0.004 | AT6: -0.003 | AU6: 0.084 | AV6: 0.058 | AW6: 0.052 | AX6: 0.008 | AY6: 0.014 | AZ6: 0 | BA6: 0.008 | BB6: 0.01 | BC6: 0.005 | BD6: 0.089 | BE6: 0.058 | BF6: 0.016 | BG6: 0.075 | BH6: 0.059 | BI6: 0.029 | BJ6: 0.028 | BK6: 0.019 | BL6: 0.046 | BM6: -0.01
A7: 355 | B7: 0.037 | C7: 0.066 | D7: 0.089 | E7: 0.078 | F7: 0.018 | G7: 0.03 | H7: 0.033 | I7: -0.051 | J7: 0.017 | K7: -0.001 | L7: 0.01 | M7: 0.095 | N7: 0.017 | O7: 0.016 | P7: 0.014 | Q7: 0.045 | R7: 0.041 | S7: 0.057 | T7: 0.039 | U7: 0.063 | V7: 0.017 | W7: 0.011 | X7: 0.007 | Y7: 0.082 | Z7: 0.005 | AA7: 0.003 | AB7: 0.054 | AC7: 0.094 | AD7: 0.006 | AE7: 0.009 | AF7: 0.052 | AG7: 0.068 | AH7: 0.046 | AI7: 0.063 | AJ7: 0.067 | AK7: 0.041 | AL7: 0.062 | AM7: 0.036 | AN7: 0.064 | AO7: 0.069 | AP7: 0.01 | AQ7: 0.019 | AR7: -0.012 | AS7: 0.004 | AT7: 0.001 | AU7: 0.086 | AV7: 0.062 | AW7: 0.063 | AX7: 0.018 | AY7: 0.017 | AZ7: 0 | BA7: 0.01 | BB7: 0 | BC7: -0.001 | BD7: 0.084 | BE7: 0.054 | BF7: 0.018 | BG7: 0.073 | BH7: 0.059 | BI7: 0.032 | BJ7: 0.025 | BK7: 0.014 | BL7: 0.041 | BM7: -0.008
A8: 356 | B8: 0.033 | C8: 0.063 | D8: 0.08 | E8: 0.076 | F8: 0.006 | G8: 0.024 | H8: 0.023 | I8: -0.048 | J8: 0.012 | K8: 0.006 | L8: 0.009 | M8: 0.088 | N8: 0.022 | O8: 0.02 | P8: 0.013 | Q8: 0.048 | R8: 0.045 | S8: 0.055 | T8: 0.04 | U8: 0.059 | V8: 0.008 | W8: 0.001 | X8: 0.001 | Y8: 0.073 | Z8: 0.008 | AA8: -0.003 | AB8: 0.064 | AC8: 0.098 | AD8: 0.008 | AE8: 0.003 | AF8: 0.061 | AG8: 0.073 | AH8: 0.052 | AI8: 0.073 | AJ8: 0.069 | AK8: 0.044 | AL8: 0.063 | AM8: 0.033 | AN8: 0.076 | AO8: 0.073 | AP8: 0.002 | AQ8: 0.011 | AR8: -0.013 | AS8: -0.003 | AT8: -0.001 | AU8: 0.087 | AV8: 0.058 | AW8: 0.053 | AX8: 0.017 | AY8: 0.011 | AZ8: 0.009 | BA8: 0.019 | BB8: 0.006 | BC8: 0.006 | BD8: 0.079 | BE8: 0.048 | BF8: 0.017 | BG8: 0.06 | BH8: 0.052 | BI8: 0.015 | BJ8: 0.011 | BK8: 0.007 | BL8: 0.033 | BM8: -0.008
A9: 357 | B9: 0.035 | C9: 0.062 | D9: 0.074 | E9: 0.069 | F9: 0 | G9: 0.024 | H9: 0.03 | I9: -0.053 | J9: 0.01 | K9: 0.009 | L9: 0.014 | M9: 0.086 | N9: 0.018 | O9: 0.005 | P9: 0.022 | Q9: 0.053 | R9: 0.056 | S9: 0.052 | T9: 0.029 | U9: 0.053 | V9: 0.015 | W9: 0.007 | X9: 0.008 | Y9: 0.074 | Z9: 0.014 | AA9: 0.01 | AB9: 0.065 | AC9: 0.098 | AD9: 0.009 | AE9: -0.002 | AF9: 0.061 | AG9: 0.069 | AH9: 0.049 | AI9: 0.07 | AJ9: 0.061 | AK9: 0.045 | AL9: 0.055 | AM9: 0.027 | AN9: 0.07 | AO9: 0.073 | AP9: 0.002 | AQ9: 0.013 | AR9: -0.015 | AS9: 0.001 | AT9: 0 | AU9: 0.089 | AV9: 0.056 | AW9: 0.046 | AX9: 0.017 | AY9: 0.009 | AZ9: 0.003 | BA9: 0.017 | BB9: 0.014 | BC9: 0.006 | BD9: 0.086 | BE9: 0.054 | BF9: 0.016 | BG9: 0.064 | BH9: 0.052 | BI9: 0.021 | BJ9: 0.007 | BK9: 0.011 | BL9: 0.031 | BM9: -0.004
A10: 358 | B10: 0.036 | C10: 0.057 | D10: 0.064 | E10: 0.068 | F10: -0.001 | G10: 0.025 | H10: 0.035 | I10: -0.044 | J10: 0.015 | K10: 0.004 | L10: 0.03 | M10: 0.096 | N10: 0.019 | O10: 0.005 | P10: 0.015 | Q10: 0.044 | R10: 0.047 | S10: 0.05 | T10: 0.031 | U10: 0.055 | V10: 0.018 | W10: 0.002 | X10: 0.011 | Y10: 0.083 | Z10: 0 | AA10: 0 | AB10: 0.05 | AC10: 0.087 | AD10: 0.008 | AE10: -0.003 | AF10: 0.044 | AG10: 0.068 | AH10: 0.042 | AI10: 0.066 | AJ10: 0.062 | AK10: 0.041 | AL10: 0.053 | AM10: 0.031 | AN10: 0.055 | AO10: 0.067 | AP10: -0.001 | AQ10: 0.003 | AR10: -0.016 | AS10: -0.003 | AT10: 0.008 | AU10: 0.093 | AV10: 0.052 | AW10: 0.051 | AX10: 0.024 | AY10: 0.02 | AZ10: 0.002 | BA10: 0.006 | BB10: 0 | BC10: 0.008 | BD10: 0.077 | BE10: 0.046 | BF10: 0.007 | BG10: 0.057 | BH10: 0.042 | BI10: 0.013 | BJ10: 0.003 | BK10: 0.01 | BL10: 0.028 | BM10: -0.012
A11: 359 | B11: 0.04 | C11: 0.057 | D11: 0.063 | E11: 0.075 | F11: 0.008 | G11: 0.019 | H11: 0.032 | I11: -0.048 | J11: 0.014 | K11: 0.002 | L11: 0.025 | M11: 0.086 | N11: 0.025 | O11: 0.004 | P11: 0.014 | Q11: 0.05 | R11: 0.055 | S11: 0.061 | T11: 0.029 | U11: 0.052 | V11: 0.019 | W11: 0 | X11: 0.012 | Y11: 0.081 | Z11: 0.003 | AA11: 0.008 | AB11: 0.054 | AC11: 0.092 | AD11: -0.006 | AE11: -0.003 | AF11: 0.047 | AG11: 0.082 | AH11: 0.042 | AI11: 0.066 | AJ11: 0.057 | AK11: 0.029 | AL11: 0.049 | AM11: 0.034 | AN11: 0.063 | AO11: 0.068 | AP11: -0.011 | AQ11: 0.003 | AR11: -0.023 | AS11: -0.011 | AT11: -0.004 | AU11: 0.09 | AV11: 0.044 | AW11: 0.045 | AX11: 0.023 | AY11: 0.026 | AZ11: 0.011 | BA11: 0.025 | BB11: -0.003 | BC11: 0.002 | BD11: 0.068 | BE11: 0.044 | BF11: 0.012 | BG11: 0.06 | BH11: 0.043 | BI11: 0.013 | BJ11: 0.008 | BK11: 0.012 | BL11: 0.038 | BM11: -0.009
A12: 360 | B12: 0.032 | C12: 0.066 | D12: 0.071 | E12: 0.074 | F12: 0.007 | G12: 0.026 | H12: 0.032 | I12: -0.049 | J12: 0.013 | K12: 0.004 | L12: 0.014 | M12: 0.092 | N12: 0.022 | O12: 0.004 | P12: 0.007 | Q12: 0.048 | R12: 0.05 | S12: 0.055 | T12: 0.025 | U12: 0.047 | V12: 0.026 | W12: 0.009 | X12: 0.018 | Y12: 0.085 | Z12: -0.001 | AA12: 0.006 | AB12: 0.054 | AC12: 0.093 | AD12: -0.002 | AE12: 0.005 | AF12: 0.038 | AG12: 0.072 | AH12: 0.047 | AI12: 0.062 | AJ12: 0.057 | AK12: 0.037 | AL12: 0.046 | AM12: 0.019 | AN12: 0.066 | AO12: 0.06 | AP12: 0.001 | AQ12: 0.007 | AR12: -0.015 | AS12: -0.011 | AT12: -0.007 | AU12: 0.09 | AV12: 0.044 | AW12: 0.048 | AX12: 0.018 | AY12: 0.017 | AZ12: 0.005 | BA12: 0.011 | BB12: -0.012 | BC12: -0.007 | BD12: 0.064 | BE12: 0.044 | BF12: 0.009 | BG12: 0.052 | BH12: 0.044 | BI12: 0.011 | BJ12: 0.003 | BK12: 0.009 | BL12: 0.036 | BM12: -0.011
A13: 361 | B13: 0.033 | C13: 0.071 | D13: 0.074 | E13: 0.074 | F13: 0.012 | G13: 0.033 | H13: 0.026 | I13: -0.035 | J13: 0.007 | K13: 0.001 | L13: 0.009 | M13: 0.085 | N13: 0.018 | O13: 0.011 | P13: 0.011 | Q13: 0.051 | R13: 0.051 | S13: 0.064 | T13: 0.025 | U13: 0.05 | V13: 0.038 | W13: 0.021 | X13: 0.007 | Y13: 0.078 | Z13: -0.005 | AA13: 0.007 | AB13: 0.052 | AC13: 0.09 | AD13: -0.004 | AE13: 0 | AF13: 0.037 | AG13: 0.07 | AH13: 0.037 | AI13: 0.057 | AJ13: 0.064 | AK13: 0.041 | AL13: 0.047 | AM13: 0.019 | AN13: 0.066 | AO13: 0.062 | AP13: 0.003 | AQ13: 0.003 | AR13: -0.013 | AS13: -0.001 | AT13: -0.002 | AU13: 0.089 | AV13: 0.037 | AW13: 0.047 | AX13: 0.021 | AY13: 0.019 | AZ13: 0.003 | BA13: 0.01 | BB13: -0.002 | BC13: -0.005 | BD13: 0.074 | BE13: 0.045 | BF13: 0.015 | BG13: 0.058 | BH13: 0.052 | BI13: 0.019 | BJ13: 0.015 | BK13: 0.014 | BL13: 0.04 | BM13: 0.002
... A402: 750 | B402: 0.005 | C402: -0.005 | D402: 0.001 | E402: 0.012 | F402: 0.004 | G402: 0.015 | H402: 0.012 | I402: 0.019 | J402: 0.008 | K402: -0.002 | L402: -0.002 | M402: -0.005 | N402: 0.004 | O402: 0.009 | P402: 0.01 | Q402: 0.005 | R402: -0.004 | S402: -0.001 | T402: -0.001 | U402: -0.004 | V402: -0.003 | W402: 0.005 | X402: -0.001 | Y402: -0.007 | Z402: -0.011 | AA402: 0.005 | AB402: -0.006 | AC402: -0.007 | AD402: 0.008 | AE402: 0.007 | AF402: 0.007 | AG402: 0.008 | AH402: 0.008 | AI402: 0.016 | AJ402: 0.013 | AK402: 0.017 | AL402: 0.016 | AM402: 0.026 | AN402: 0.023 | AO402: 0.016 | AP402: -0.008 | AQ402: -0.007 | AR402: -0.022 | AS402: -0.015 | AT402: 0.011 | AU402: -0.011 | AV402: -0.014 | AW402: 0.001 | AX402: 0.011 | AY402: 0.013 | AZ402: 0.02 | BA402: 0.025 | BB402: -0.004 | BC402: -0.012 | BD402: -0.009 | BE402: -0.002 | BF402: 0.007 | BG402: -0.005 | BH402: -0.005 | BI402: 0.006 | BJ402: 0.011 | BK402: 0.007 | BL402: 0.017 | BM402: 0.018

Sheet Avg Spectra
U1: Normalized | V1: 0.006 | W1: 0.0026 | X1: 0.0007 | Y1: 0.0022 | AA1: 0.0015
B2: VS | E2: SWS | H2: MWS | K2: LWS | N2: DC | Q2: RH1 | V2: 0.0135 | W2: 0.007 | X2: 0.0145 | Y2: 0.0024 | AA2: 0.0405
A3: wl | B3: Sample | C3: Bleach | D3: Difference | E3: Sample | F3: Bleach | G3: Difference | H3: Sample | I3: Bleach | J3: Difference | K3: Sample | L3: Bleach | M3: Difference | N3: Sample | O3: Bleach | P3: Difference | Q3: Sample | R3: Bleach | S3: Difference | U3: wl | V3: vs | W3: sws | X3: mws | Y3: lws | Z3: dc | AA3: rh1
A4: 350 | B4: =AVERAGE('Raw Data'!J2,'Raw Data'!AD2,'Raw Data'!AL2,'Raw Data'!AX2) -> 0.02525 | C4: =AVERAGE('Raw Data'!K2,'Raw Data'!AE2,'Raw Data'!AM2,'Raw Data'!AY2) -> 0.00975 | D4: =B4-C4 -> 0.0155 | E4: =AVERAGE('Raw Data'!N2,'Raw Data'!AN2,'Raw Data'!AR2,'Raw Data'!AZ2,'Raw Data'!BB2,'Raw Data'!BJ2) -> 0.016 | F4: =AVERAGE('Raw Data'!O2,'Raw Data'!AO2,'Raw Data'!AS2,'Raw Data'!BA2,'Raw Data'!BC2,'Raw Data'!BK2) -> 0.0175 | G4: =E4-F4 -> -0.0015 | H4: =AVERAGE('Raw Data'!F2,'Raw Data'!R2,'Raw Data'!V2,'Raw Data'!X2,'Raw Data'!Z2,'Raw Data'!AH2,'Raw Data'!AV2,'Raw Data'!BH2,'Raw Data'!BL2) -> 0.034444444 | I4: =AVERAGE('Raw Data'!G2,'Raw Data'!S2,'Raw Data'!W2,'Raw Data'!Y2,'Raw Data'!AA2,'Raw Data'!AI2,'Raw Data'!AW2,'Raw Data'!BI2,'Raw Data'!BM2) -> 0.039555556 | J4: =H4-I4 -> -0.0051111111 | K4: =AVERAGE('Raw Data'!H2,'Raw Data'!AJ2,'Raw Data'!AP2) -> 0.026666667 | L4: =AVERAGE('Raw Data'!I2,'Raw Data'!AK2,'Raw Data'!AQ2) -> -0.01 | M4: =K4-L4 -> 0.036666667 | N4: =AVERAGE('Raw Data'!P2) -> 0.027 | O4: =AVERAGE('Raw Data'!Q2) -> 0.056 | P4: =N4-O4 -> -0.029 | Q4: =AVERAGE('Raw Data'!B2,'Raw Data'!D2,'Raw Data'!L2,'Raw Data'!T2,'Raw Data'!AB2,'Raw Data'!AF2,'Raw Data'!AT2,'Raw Data'!BD2,'Raw Data'!BF2) -> 0.041222222 | R4: =AVERAGE('Raw Data'!C2,'Raw Data'!E2,'Raw Data'!M2,'Raw Data'!U2,'Raw Data'!AC2,'Raw Data'!AG2,'Raw Data'!AU2,'Raw Data'!BE2,'Raw Data'!BG2) -> 0.070777778 | S4: =Q4-R4 -> -0.029555556 | U4: 350 | V4: =(B4-V$1)/V$2 -> 1.4259259 | W4: =(E4-W$1)/W$2 -> 1.9142857 | X4: =(H4-X$1)/X$2 -> 2.3272031 | Y4: =(K4-Y$1)/Y$2 -> 10.194444 | Z4: =(N4-Z$1)/Z$2 -> #DIV/0! | AA4: =(Q4-AA$1)/AA$2 -> 0.98079561
A5: 351 | B5: =AVERAGE('Raw Data'!J3,'Raw Data'!AD3,'Raw Data'!AL3,'Raw Data'!AX3) -> 0.02475 | C5: =AVERAGE('Raw Data'!K3,'Raw Data'!AE3,'Raw Data'!AM3,'Raw Data'!AY3) -> 0.00875 | D5: =B5-C5 -> 0.016 | E5: =AVERAGE('Raw Data'!N3,'Raw Data'!AN3,'Raw Data'!AR3,'Raw Data'!AZ3,'Raw Data'!BB3,'Raw Data'!BJ3) -> 0.009 | F5: =AVERAGE('Raw Data'!O3,'Raw Data'!AO3,'Raw Data'!AS3,'Raw Data'!BA3,'Raw Data'!BC3,'Raw Data'!BK3) -> 0.016 | G5: =E5-F5 -> -0.007 | H5: =AVERAGE('Raw Data'!F3,'Raw Data'!R3,'Raw Data'!V3,'Raw Data'!X3,'Raw Data'!Z3,'Raw Data'!AH3,'Raw Data'!AV3,'Raw Data'!BH3,'Raw Data'!BL3) -> 0.031444444 | I5: =AVERAGE('Raw Data'!G3,'Raw Data'!S3,'Raw Data'!W3,'Raw Data'!Y3,'Raw Data'!AA3,'Raw Data'!AI3,'Raw Data'!AW3,'Raw Data'!BI3,'Raw Data'!BM3) -> 0.035222222 | J5: =H5-I5 -> -0.0037777778 | K5: =AVERAGE('Raw Data'!H3,'Raw Data'!AJ3,'Raw Data'!AP3) -> 0.03 | L5: =AVERAGE('Raw Data'!I3,'Raw Data'!AK3,'Raw Data'!AQ3) -> -0.0093333333 | M5: =K5-L5 -> 0.039333333 | N5: =AVERAGE('Raw Data'!P3) -> 0.015 | O5: =AVERAGE('Raw Data'!Q3) -> 0.045 | P5: =N5-O5 -> -0.03 | Q5: =AVERAGE('Raw Data'!B3,'Raw Data'!D3,'Raw Data'!L3,'Raw Data'!T3,'Raw Data'!AB3,'Raw Data'!AF3,'Raw Data'!AT3,'Raw Data'!BD3,'Raw Data'!BF3) -> 0.043555556 | R5: =AVERAGE('Raw Data'!C3,'Raw Data'!E3,'Raw Data'!M3,'Raw Data'!U3,'Raw Data'!AC3,'Raw Data'!AG3,'Raw Data'!AU3,'Raw Data'!BE3,'Raw Data'!BG3) -> 0.073111111 | S5: =Q5-R5 -> -0.029555556 | U5: 351 | V5: =(B5-V$1)/V$2 -> 1.3888889 | W5: =(E5-W$1)/W$2 -> 0.91428571 | X5: =(H5-X$1)/X$2 -> 2.1203065 | Y5: =(K5-Y$1)/Y$2 -> 11.583333 | Z5: =(N5-Z$1)/Z$2 -> #DIV/0! | AA5: =(Q5-AA$1)/AA$2 -> 1.0384088
A6: 352 | B6: =AVERAGE('Raw Data'!J4,'Raw Data'!AD4,'Raw Data'!AL4,'Raw Data'!AX4) -> 0.01875 | C6: =AVERAGE('Raw Data'!K4,'Raw Data'!AE4,'Raw Data'!AM4,'Raw Data'!AY4) -> 0.00875 | D6: =B6-C6 -> 0.01 | E6: =AVERAGE('Raw Data'!N4,'Raw Data'!AN4,'Raw Data'!AR4,'Raw Data'!AZ4,'Raw Data'!BB4,'Raw Data'!BJ4) -> 0.0115 | F6: =AVERAGE('Raw Data'!O4,'Raw Data'!AO4,'Raw Data'!AS4,'Raw Data'!BA4,'Raw Data'!BC4,'Raw Data'!BK4) -> 0.0165 | G6: =E6-F6 -> -0.005 | H6: =AVERAGE('Raw Data'!F4,'Raw Data'!R4,'Raw Data'!V4,'Raw Data'!X4,'Raw Data'!Z4,'Raw Data'!AH4,'Raw Data'!AV4,'Raw Data'!BH4,'Raw Data'!BL4) -> 0.032 | I6: =AVERAGE('Raw Data'!G4,'Raw Data'!S4,'Raw Data'!W4,'Raw Data'!Y4,'Raw Data'!AA4,'Raw Data'!AI4,'Raw Data'!AW4,'Raw Data'!BI4,'Raw Data'!BM4) -> 0.033666667 | J6: =H6-I6 -> -0.0016666667 | K6: =AVERAGE('Raw Data'!H4,'Raw Data'!AJ4,'Raw Data'!AP4) -> 0.027 | L6: =AVERAGE('Raw Data'!I4,'Raw Data'!AK4,'Raw Data'!AQ4) -> -0.01 | M6: =K6-L6 -> 0.037 | N6: =AVERAGE('Raw Data'!P4) -> 0.007 | O6: =AVERAGE('Raw Data'!Q4) -> 0.041 | P6: =N6-O6 -> -0.034 | Q6: =AVERAGE('Raw Data'!B4,'Raw Data'!D4,'Raw Data'!L4,'Raw Data'!T4,'Raw Data'!AB4,'Raw Data'!AF4,'Raw Data'!AT4,'Raw Data'!BD4,'Raw Data'!BF4) -> 0.040222222 | R6: =AVERAGE('Raw Data'!C4,'Raw Data'!E4,'Raw Data'!M4,'Raw Data'!U4,'Raw Data'!AC4,'Raw Data'!AG4,'Raw Data'!AU4,'Raw Data'!BE4,'Raw Data'!BG4) -> 0.068888889 | S6: =Q6-R6 -> -0.028666667 | U6: 352 | V6: =(B6-V$1)/V$2 -> 0.94444444 | W6: =(E6-W$1)/W$2 -> 1.2714286 | X6: =(H6-X$1)/X$2 -> 2.1586207 | Y6: =(K6-Y$1)/Y$2 -> 10.333333 | Z6: =(N6-Z$1)/Z$2 -> #DIV/0! | AA6: =(Q6-AA$1)/AA$2 -> 0.95610425
A7: 353 | B7: =AVERAGE('Raw Data'!J5,'Raw Data'!AD5,'Raw Data'!AL5,'Raw Data'!AX5) -> 0.01875 | C7: =AVERAGE('Raw Data'!K5,'Raw Data'!AE5,'Raw Data'!AM5,'Raw Data'!AY5) -> 0.0115 | D7: =B7-C7 -> 0.00725 | E7: =AVERAGE('Raw Data'!N5,'Raw Data'!AN5,'Raw Data'!AR5,'Raw Data'!AZ5,'Raw Data'!BB5,'Raw Data'!BJ5) -> 0.018166667 | F7: =AVERAGE('Raw Data'!O5,'Raw Data'!AO5,'Raw Data'!AS5,'Raw Data'!BA5,'Raw Data'!BC5,'Raw Data'!BK5) -> 0.017666667 | G7: =E7-F7 -> 0.0005 | H7: =AVERAGE('Raw Data'!F5,'Raw Data'!R5,'Raw Data'!V5,'Raw Data'!X5,'Raw Data'!Z5,'Raw Data'!AH5,'Raw Data'!AV5,'Raw Data'!BH5,'Raw Data'!BL5) -> 0.033222222 | I7: =AVERAGE('Raw Data'!G5,'Raw Data'!S5,'Raw Data'!W5,'Raw Data'!Y5,'Raw Data'!AA5,'Raw Data'!AI5,'Raw Data'!AW5,'Raw Data'!BI5,'Raw Data'!BM5) -> 0.037444444 | J7: =H7-I7 -> -0.0042222222 | K7: =AVERAGE('Raw Data'!H5,'Raw Data'!AJ5,'Raw Data'!AP5) -> 0.028666667 | L7: =AVERAGE('Raw Data'!I5,'Raw Data'!AK5,'Raw Data'!AQ5) -> -0.014666667 | M7: =K7-L7 -> 0.043333333 | N7: =AVERAGE('Raw Data'!P5) -> 0.014 | O7: =AVERAGE('Raw Data'!Q5) -> 0.046 | P7: =N7-O7 -> -0.032 | Q7: =AVERAGE('Raw Data'!B5,'Raw Data'!D5,'Raw Data'!L5,'Raw Data'!T5,'Raw Data'!AB5,'Raw Data'!AF5,'Raw Data'!AT5,'Raw Data'!BD5,'Raw Data'!BF5) -> 0.041666667 | R7: =AVERAGE('Raw Data'!C5,'Raw Data'!E5,'Raw Data'!M5,'Raw Data'!U5,'Raw Data'!AC5,'Raw Data'!AG5,'Raw Data'!AU5,'Raw Data'!BE5,'Raw Data'!BG5) -> 0.072666667 | S7: =Q7-R7 -> -0.031 | U7: 353 | V7: =(B7-V$1)/V$2 -> 0.94444444 | W7: =(E7-W$1)/W$2 -> 2.2238095 | X7: =(H7-X$1)/X$2 -> 2.2429119 | Y7: =(K7-Y$1)/Y$2 -> 11.027778 | Z7: =(N7-Z$1)/Z$2 -> #DIV/0! | AA7: =(Q7-AA$1)/AA$2 -> 0.99176955
A8: 354 | B8: =AVERAGE('Raw Data'!J6,'Raw Data'!AD6,'Raw Data'!AL6,'Raw Data'!AX6) -> 0.019 | C8: =AVERAGE('Raw Data'!K6,'Raw Data'!AE6,'Raw Data'!AM6,'Raw Data'!AY6) -> 0.0105 | D8: =B8-C8 -> 0.0085 | E8: =AVERAGE('Raw Data'!N6,'Raw Data'!AN6,'Raw Data'!AR6,'Raw Data'!AZ6,'Raw Data'!BB6,'Raw Data'!BJ6) -> 0.019666667 | F8: =AVERAGE('Raw Data'!O6,'Raw Data'!AO6,'Raw Data'!AS6,'Raw Data'!BA6,'Raw Data'!BC6,'Raw Data'!BK6) -> 0.0195 | G8: =E8-F8 -> 0.00016666667 | H8: =AVERAGE('Raw Data'!F6,'Raw Data'!R6,'Raw Data'!V6,'Raw Data'!X6,'Raw Data'!Z6,'Raw Data'!AH6,'Raw Data'!AV6,'Raw Data'!BH6,'Raw Data'!BL6) -> 0.033666667 | I8: =AVERAGE('Raw Data'!G6,'Raw Data'!S6,'Raw Data'!W6,'Raw Data'!Y6,'Raw Data'!AA6,'Raw Data'!AI6,'Raw Data'!AW6,'Raw Data'!BI6,'Raw Data'!BM6) -> 0.035555556 | J8: =H8-I8 -> -0.0018888889 | K8: =AVERAGE('Raw Data'!H6,'Raw Data'!AJ6,'Raw Data'!AP6) -> 0.035666667 | L8: =AVERAGE('Raw Data'!I6,'Raw Data'!AK6,'Raw Data'!AQ6) -> -0.0073333333 | M8: =K8-L8 -> 0.043 | N8: =AVERAGE('Raw Data'!P6) -> 0.013 | O8: =AVERAGE('Raw Data'!Q6) -> 0.042 | P8: =N8-O8 -> -0.029 | Q8: =AVERAGE('Raw Data'!B6,'Raw Data'!D6,'Raw Data'!L6,'Raw Data'!T6,'Raw Data'!AB6,'Raw Data'!AF6,'Raw Data'!AT6,'Raw Data'!BD6,'Raw Data'!BF6) -> 0.042888889 | R8: =AVERAGE('Raw Data'!C6,'Raw Data'!E6,'Raw Data'!M6,'Raw Data'!U6,'Raw Data'!AC6,'Raw Data'!AG6,'Raw Data'!AU6,'Raw Data'!BE6,'Raw Data'!BG6) -> 0.075111111 | S8: =Q8-R8 -> -0.032222222 | U8: 354 | V8: =(B8-V$1)/V$2 -> 0.96296296 | W8: =(E8-W$1)/W$2 -> 2.4380952 | X8: =(H8-X$1)/X$2 -> 2.2735632 | Y8: =(K8-Y$1)/Y$2 -> 13.944444 | Z8: =(N8-Z$1)/Z$2 -> #DIV/0! | AA8: =(Q8-AA$1)/AA$2 -> 1.0219479
A9: 355 | B9: =AVERAGE('Raw Data'!J7,'Raw Data'!AD7,'Raw Data'!AL7,'Raw Data'!AX7) -> 0.02575 | C9: =AVERAGE('Raw Data'!K7,'Raw Data'!AE7,'Raw Data'!AM7,'Raw Data'!AY7) -> 0.01525 | D9: =B9-C9 -> 0.0105 | E9: =AVERAGE('Raw Data'!N7,'Raw Data'!AN7,'Raw Data'!AR7,'Raw Data'!AZ7,'Raw Data'!BB7,'Raw Data'!BJ7) -> 0.015666667 | F9: =AVERAGE('Raw Data'!O7,'Raw Data'!AO7,'Raw Data'!AS7,'Raw Data'!BA7,'Raw Data'!BC7,'Raw Data'!BK7) -> 0.018666667 | G9: =E9-F9 -> -0.003 | H9: =AVERAGE('Raw Data'!F7,'Raw Data'!R7,'Raw Data'!V7,'Raw Data'!X7,'Raw Data'!Z7,'Raw Data'!AH7,'Raw Data'!AV7,'Raw Data'!BH7,'Raw Data'!BL7) -> 0.032888889 | I9: =AVERAGE('Raw Data'!G7,'Raw Data'!S7,'Raw Data'!W7,'Raw Data'!Y7,'Raw Data'!AA7,'Raw Data'!AI7,'Raw Data'!AW7,'Raw Data'!BI7,'Raw Data'!BM7) -> 0.037 | J9: =H9-I9 -> -0.0041111111 | K9: =AVERAGE('Raw Data'!H7,'Raw Data'!AJ7,'Raw Data'!AP7) -> 0.036666667 | L9: =AVERAGE('Raw Data'!I7,'Raw Data'!AK7,'Raw Data'!AQ7) -> 0.003 | M9: =K9-L9 -> 0.033666667 | N9: =AVERAGE('Raw Data'!P7) -> 0.014 | O9: =AVERAGE('Raw Data'!Q7) -> 0.045 | P9: =N9-O9 -> -0.031 | Q9: =AVERAGE('Raw Data'!B7,'Raw Data'!D7,'Raw Data'!L7,'Raw Data'!T7,'Raw Data'!AB7,'Raw Data'!AF7,'Raw Data'!AT7,'Raw Data'!BD7,'Raw Data'!BF7) -> 0.042666667 | R9: =AVERAGE('Raw Data'!C7,'Raw Data'!E7,'Raw Data'!M7,'Raw Data'!U7,'Raw Data'!AC7,'Raw Data'!AG7,'Raw Data'!AU7,'Raw Data'!BE7,'Raw Data'!BG7) -> 0.075222222 | S9: =Q9-R9 -> -0.032555556 | U9: 355 | V9: =(B9-V$1)/V$2 -> 1.462963 | W9: =(E9-W$1)/W$2 -> 1.8666667 | X9: =(H9-X$1)/X$2 -> 2.2199234 | Y9: =(K9-Y$1)/Y$2 -> 14.361111 | Z9: =(N9-Z$1)/Z$2 -> #DIV/0! | AA9: =(Q9-AA$1)/AA$2 -> 1.0164609
A10: 356 | B10: =AVERAGE('Raw Data'!J8,'Raw Data'!AD8,'Raw Data'!AL8,'Raw Data'!AX8) -> 0.025 | C10: =AVERAGE('Raw Data'!K8,'Raw Data'!AE8,'Raw Data'!AM8,'Raw Data'!AY8) -> 0.01325 | D10: =B10-C10 -> 0.01175 | E10: =AVERAGE('Raw Data'!N8,'Raw Data'!AN8,'Raw Data'!AR8,'Raw Data'!AZ8,'Raw Data'!BB8,'Raw Data'!BJ8) -> 0.0185 | F10: =AVERAGE('Raw Data'!O8,'Raw Data'!AO8,'Raw Data'!AS8,'Raw Data'!BA8,'Raw Data'!BC8,'Raw Data'!BK8) -> 0.020333333 | G10: =E10-F10 -> -0.0018333333 | H10: =AVERAGE('Raw Data'!F8,'Raw Data'!R8,'Raw Data'!V8,'Raw Data'!X8,'Raw Data'!Z8,'Raw Data'!AH8,'Raw Data'!AV8,'Raw Data'!BH8,'Raw Data'!BL8) -> 0.029222222 | I10: =AVERAGE('Raw Data'!G8,'Raw Data'!S8,'Raw Data'!W8,'Raw Data'!Y8,'Raw Data'!AA8,'Raw Data'!AI8,'Raw Data'!AW8,'Raw Data'!BI8,'Raw Data'!BM8) -> 0.031444444 | J10: =H10-I10 -> -0.0022222222 | K10: =AVERAGE('Raw Data'!H8,'Raw Data'!AJ8,'Raw Data'!AP8) -> 0.031333333 | L10: =AVERAGE('Raw Data'!I8,'Raw Data'!AK8,'Raw Data'!AQ8) -> 0.0023333333 | M10: =K10-L10 -> 0.029 | N10: =AVERAGE('Raw Data'!P8) -> 0.013 | O10: =AVERAGE('Raw Data'!Q8) -> 0.048 | P10: =N10-O10 -> -0.035 | Q10: =AVERAGE('Raw Data'!B8,'Raw Data'!D8,'Raw Data'!L8,'Raw Data'!T8,'Raw Data'!AB8,'Raw Data'!AF8,'Raw Data'!AT8,'Raw Data'!BD8,'Raw Data'!BF8) -> 0.042444444 | R10: =AVERAGE('Raw Data'!C8,'Raw Data'!E8,'Raw Data'!M8,'Raw Data'!U8,'Raw Data'!AC8,'Raw Data'!AG8,'Raw Data'!AU8,'Raw Data'!BE8,'Raw Data'!BG8) -> 0.072444444 | S10: =Q10-R10 -> -0.03 | U10: 356 | V10: =(B10-V$1)/V$2 -> 1.4074074 | W10: =(E10-W$1)/W$2 -> 2.2714286 | X10: =(H10-X$1)/X$2 -> 1.9670498 | Y10: =(K10-Y$1)/Y$2 -> 12.138889 | Z10: =(N10-Z$1)/Z$2 -> #DIV/0! | AA10: =(Q10-AA$1)/AA$2 -> 1.0109739
A11: 357 | B11: =AVERAGE('Raw Data'!J9,'Raw Data'!AD9,'Raw Data'!AL9,'Raw Data'!AX9) -> 0.02275 | C11: =AVERAGE('Raw Data'!K9,'Raw Data'!AE9,'Raw Data'!AM9,'Raw Data'!AY9) -> 0.01075 | D11: =B11-C11 -> 0.012 | E11: =AVERAGE('Raw Data'!N9,'Raw Data'!AN9,'Raw Data'!AR9,'Raw Data'!AZ9,'Raw Data'!BB9,'Raw Data'!BJ9) -> 0.016166667 | F11: =AVERAGE('Raw Data'!O9,'Raw Data'!AO9,'Raw Data'!AS9,'Raw Data'!BA9,'Raw Data'!BC9,'Raw Data'!BK9) -> 0.018833333 | G11: =E11-F11 -> -0.0026666667 | H11: =AVERAGE('Raw Data'!F9,'Raw Data'!R9,'Raw Data'!V9,'Raw Data'!X9,'Raw Data'!Z9,'Raw Data'!AH9,'Raw Data'!AV9,'Raw Data'!BH9,'Raw Data'!BL9) -> 0.031222222 | I11: =AVERAGE('Raw Data'!G9,'Raw Data'!S9,'Raw Data'!W9,'Raw Data'!Y9,'Raw Data'!AA9,'Raw Data'!AI9,'Raw Data'!AW9,'Raw Data'!BI9,'Raw Data'!BM9) -> 0.033333333 | J11: =H11-I11 -> -0.0021111111 | K11: =AVERAGE('Raw Data'!H9,'Raw Data'!AJ9,'Raw Data'!AP9) -> 0.031 | L11: =AVERAGE('Raw Data'!I9,'Raw Data'!AK9,'Raw Data'!AQ9) -> 0.0016666667 | M11: =K11-L11 -> 0.029333333 | N11: =AVERAGE('Raw Data'!P9) -> 0.022 | O11: =AVERAGE('Raw Data'!Q9) -> 0.053 | P11: =N11-O11 -> -0.031 | Q11: =AVERAGE('Raw Data'!B9,'Raw Data'!D9,'Raw Data'!L9,'Raw Data'!T9,'Raw Data'!AB9,'Raw Data'!AF9,'Raw Data'!AT9,'Raw Data'!BD9,'Raw Data'!BF9) -> 0.042222222 | R11: =AVERAGE('Raw Data'!C9,'Raw Data'!E9,'Raw Data'!M9,'Raw Data'!U9,'Raw Data'!AC9,'Raw Data'!AG9,'Raw Data'!AU9,'Raw Data'!BE9,'Raw Data'!BG9) -> 0.071555556 | S11: =Q11-R11 -> -0.029333333 | U11: 357 | V11: =(B11-V$1)/V$2 -> 1.2407407 | W11: =(E11-W$1)/W$2 -> 1.9380952 | X11: =(H11-X$1)/X$2 -> 2.1049808 | Y11: =(K11-Y$1)/Y$2 -> 12 | Z11: =(N11-Z$1)/Z$2 -> #DIV/0! | AA11: =(Q11-AA$1)/AA$2 -> 1.005487
A12: 358 | B12: =AVERAGE('Raw Data'!J10,'Raw Data'!AD10,'Raw Data'!AL10,'Raw Data'!AX10) -> 0.025 | C12: =AVERAGE('Raw Data'!K10,'Raw Data'!AE10,'Raw Data'!AM10,'Raw Data'!AY10) -> 0.013 | D12: =B12-C12 -> 0.012 | E12: =AVERAGE('Raw Data'!N10,'Raw Data'!AN10,'Raw Data'!AR10,'Raw Data'!AZ10,'Raw Data'!BB10,'Raw Data'!BJ10) -> 0.0105 | F12: =AVERAGE('Raw Data'!O10,'Raw Data'!AO10,'Raw Data'!AS10,'Raw Data'!BA10,'Raw Data'!BC10,'Raw Data'!BK10) -> 0.0155 | G12: =E12-F12 -> -0.005 | H12: =AVERAGE('Raw Data'!F10,'Raw Data'!R10,'Raw Data'!V10,'Raw Data'!X10,'Raw Data'!Z10,'Raw Data'!AH10,'Raw Data'!AV10,'Raw Data'!BH10,'Raw Data'!BL10) -> 0.026555556 | I12: =AVERAGE('Raw Data'!G10,'Raw Data'!S10,'Raw Data'!W10,'Raw Data'!Y10,'Raw Data'!AA10,'Raw Data'!AI10,'Raw Data'!AW10,'Raw Data'!BI10,'Raw Data'!BM10) -> 0.030888889 | J12: =H12-I12 -> -0.0043333333 | K12: =AVERAGE('Raw Data'!H10,'Raw Data'!AJ10,'Raw Data'!AP10) -> 0.032 | L12: =AVERAGE('Raw Data'!I10,'Raw Data'!AK10,'Raw Data'!AQ10) -> 1.4456029e-18 | M12: =K12-L12 -> 0.032 | N12: =AVERAGE('Raw Data'!P10) -> 0.015 | O12: =AVERAGE('Raw Data'!Q10) -> 0.044 | P12: =N12-O12 -> -0.029 | Q12: =AVERAGE('Raw Data'!B10,'Raw Data'!D10,'Raw Data'!L10,'Raw Data'!T10,'Raw Data'!AB10,'Raw Data'!AF10,'Raw Data'!AT10,'Raw Data'!BD10,'Raw Data'!BF10) -> 0.038555556 | R12: =AVERAGE('Raw Data'!C10,'Raw Data'!E10,'Raw Data'!M10,'Raw Data'!U10,'Raw Data'!AC10,'Raw Data'!AG10,'Raw Data'!AU10,'Raw Data'!BE10,'Raw Data'!BG10) -> 0.069666667 | S12: =Q12-R12 -> -0.031111111 | U12: 358 | V12: =(B12-V$1)/V$2 -> 1.4074074 | W12: =(E12-W$1)/W$2 -> 1.1285714 | X12: =(H12-X$1)/X$2 -> 1.7831418 | Y12: =(K12-Y$1)/Y$2 -> 12.416667 | Z12: =(N12-Z$1)/Z$2 -> #DIV/0! | AA12: =(Q12-AA$1)/AA$2 -> 0.91495199
A13: 359 | B13: =AVERAGE('Raw Data'!J11,'Raw Data'!AD11,'Raw Data'!AL11,'Raw Data'!AX11) -> 0.02 | C13: =AVERAGE('Raw Data'!K11,'Raw Data'!AE11,'Raw Data'!AM11,'Raw Data'!AY11) -> 0.01475 | D13: =B13-C13 -> 0.00525 | E13: =AVERAGE('Raw Data'!N11,'Raw Data'!AN11,'Raw Data'!AR11,'Raw Data'!AZ11,'Raw Data'!BB11,'Raw Data'!BJ11) -> 0.0135 | F13: =AVERAGE('Raw Data'!O11,'Raw Data'!AO11,'Raw Data'!AS11,'Raw Data'!BA11,'Raw Data'!BC11,'Raw Data'!BK11) -> 0.016666667 | G13: =E13-F13 -> -0.0031666667 | H13: =AVERAGE('Raw Data'!F11,'Raw Data'!R11,'Raw Data'!V11,'Raw Data'!X11,'Raw Data'!Z11,'Raw Data'!AH11,'Raw Data'!AV11,'Raw Data'!BH11,'Raw Data'!BL11) -> 0.029333333 | I13: =AVERAGE('Raw Data'!G11,'Raw Data'!S11,'Raw Data'!W11,'Raw Data'!Y11,'Raw Data'!AA11,'Raw Data'!AI11,'Raw Data'!AW11,'Raw Data'!BI11,'Raw Data'!BM11) -> 0.031555556 | J13: =H13-I13 -> -0.0022222222 | K13: =AVERAGE('Raw Data'!H11,'Raw Data'!AJ11,'Raw Data'!AP11) -> 0.026 | L13: =AVERAGE('Raw Data'!I11,'Raw Data'!AK11,'Raw Data'!AQ11) -> -0.0053333333 | M13: =K13-L13 -> 0.031333333 | N13: =AVERAGE('Raw Data'!P11) -> 0.014 | O13: =AVERAGE('Raw Data'!Q11) -> 0.05 | P13: =N13-O13 -> -0.036 | Q13: =AVERAGE('Raw Data'!B11,'Raw Data'!D11,'Raw Data'!L11,'Raw Data'!T11,'Raw Data'!AB11,'Raw Data'!AF11,'Raw Data'!AT11,'Raw Data'!BD11,'Raw Data'!BF11) -> 0.037111111 | R13: =AVERAGE('Raw Data'!C11,'Raw Data'!E11,'Raw Data'!M11,'Raw Data'!U11,'Raw Data'!AC11,'Raw Data'!AG11,'Raw Data'!AU11,'Raw Data'!BE11,'Raw Data'!BG11) -> 0.070888889 | S13: =Q13-R13 -> -0.033777778 | U13: 359 | V13: =(B13-V$1)/V$2 -> 1.037037 | W13: =(E13-W$1)/W$2 -> 1.5571429 | X13: =(H13-X$1)/X$2 -> 1.9747126 | Y13: =(K13-Y$1)/Y$2 -> 9.9166667 | Z13: =(N13-Z$1)/Z$2 -> #DIV/0! | AA13: =(Q13-AA$1)/AA$2 -> 0.87928669
A14: 360 | B14: =AVERAGE('Raw Data'!J12,'Raw Data'!AD12,'Raw Data'!AL12,'Raw Data'!AX12) -> 0.01875 | C14: =AVERAGE('Raw Data'!K12,'Raw Data'!AE12,'Raw Data'!AM12,'Raw Data'!AY12) -> 0.01125 | D14: =B14-C14 -> 0.0075 | E14: =AVERAGE('Raw Data'!N12,'Raw Data'!AN12,'Raw Data'!AR12,'Raw Data'!AZ12,'Raw Data'!BB12,'Raw Data'!BJ12) -> 0.0115 | F14: =AVERAGE('Raw Data'!O12,'Raw Data'!AO12,'Raw Data'!AS12,'Raw Data'!BA12,'Raw Data'!BC12,'Raw Data'!BK12) -> 0.011 | G14: =E14-F14 -> 0.0005 | H14: =AVERAGE('Raw Data'!F12,'Raw Data'!R12,'Raw Data'!V12,'Raw Data'!X12,'Raw Data'!Z12,'Raw Data'!AH12,'Raw Data'!AV12,'Raw Data'!BH12,'Raw Data'!BL12) -> 0.030111111 | I14: =AVERAGE('Raw Data'!G12,'Raw Data'!S12,'Raw Data'!W12,'Raw Data'!Y12,'Raw Data'!AA12,'Raw Data'!AI12,'Raw Data'!AW12,'Raw Data'!BI12,'Raw Data'!BM12) -> 0.032333333 | J14: =H14-I14 -> -0.0022222222 | K14: =AVERAGE('Raw Data'!H12,'Raw Data'!AJ12,'Raw Data'!AP12) -> 0.03 | L14: =AVERAGE('Raw Data'!I12,'Raw Data'!AK12,'Raw Data'!AQ12) -> -0.0016666667 | M14: =K14-L14 -> 0.031666667 | N14: =AVERAGE('Raw Data'!P12) -> 0.007 | O14: =AVERAGE('Raw Data'!Q12) -> 0.048 | P14: =N14-O14 -> -0.041 | Q14: =AVERAGE('Raw Data'!B12,'Raw Data'!D12,'Raw Data'!L12,'Raw Data'!T12,'Raw Data'!AB12,'Raw Data'!AF12,'Raw Data'!AT12,'Raw Data'!BD12,'Raw Data'!BF12) -> 0.033333333 | R14: =AVERAGE('Raw Data'!C12,'Raw Data'!E12,'Raw Data'!M12,'Raw Data'!U12,'Raw Data'!AC12,'Raw Data'!AG12,'Raw Data'!AU12,'Raw Data'!BE12,'Raw Data'!BG12) -> 0.07 | S14: =Q14-R14 -> -0.036666667 | U14: 360 | V14: =(B14-V$1)/V$2 -> 0.94444444 | W14: =(E14-W$1)/W$2 -> 1.2714286 | X14: =(H14-X$1)/X$2 -> 2.0283525 | Y14: =(K14-Y$1)/Y$2 -> 11.583333 | Z14: =(N14-Z$1)/Z$2 -> #DIV/0! | AA14: =(Q14-AA$1)/AA$2 -> 0.78600823
A15: 361 | B15: =AVERAGE('Raw Data'!J13,'Raw Data'!AD13,'Raw Data'!AL13,'Raw Data'!AX13) -> 0.01775 | C15: =AVERAGE('Raw Data'!K13,'Raw Data'!AE13,'Raw Data'!AM13,'Raw Data'!AY13) -> 0.00975 | D15: =B15-C15 -> 0.008 | E15: =AVERAGE('Raw Data'!N13,'Raw Data'!AN13,'Raw Data'!AR13,'Raw Data'!AZ13,'Raw Data'!BB13,'Raw Data'!BJ13) -> 0.0145 | F15: =AVERAGE('Raw Data'!O13,'Raw Data'!AO13,'Raw Data'!AS13,'Raw Data'!BA13,'Raw Data'!BC13,'Raw Data'!BK13) -> 0.015166667 | G15: =E15-F15 -> -0.00066666667 | H15: =AVERAGE('Raw Data'!F13,'Raw Data'!R13,'Raw Data'!V13,'Raw Data'!X13,'Raw Data'!Z13,'Raw Data'!AH13,'Raw Data'!AV13,'Raw Data'!BH13,'Raw Data'!BL13) -> 0.029888889 | I15: =AVERAGE('Raw Data'!G13,'Raw Data'!S13,'Raw Data'!W13,'Raw Data'!Y13,'Raw Data'!AA13,'Raw Data'!AI13,'Raw Data'!AW13,'Raw Data'!BI13,'Raw Data'!BM13) -> 0.036444444 | J15: =H15-I15 -> -0.0065555556 | K15: =AVERAGE('Raw Data'!H13,'Raw Data'!AJ13,'Raw Data'!AP13) -> 0.031 | L15: =AVERAGE('Raw Data'!I13,'Raw Data'!AK13,'Raw Data'!AQ13) -> 0.003 | M15: =K15-L15 -> 0.028 | N15: =AVERAGE('Raw Data'!P13) -> 0.011 | O15: =AVERAGE('Raw Data'!Q13) -> 0.051 | P15: =N15-O15 -> -0.04 | Q15: =AVERAGE('Raw Data'!B13,'Raw Data'!D13,'Raw Data'!L13,'Raw Data'!T13,'Raw Data'!AB13,'Raw Data'!AF13,'Raw Data'!AT13,'Raw Data'!BD13,'Raw Data'!BF13) -> 0.035222222 | R15: =AVERAGE('Raw Data'!C13,'Raw Data'!E13,'Raw Data'!M13,'Raw Data'!U13,'Raw Data'!AC13,'Raw Data'!AG13,'Raw Data'!AU13,'Raw Data'!BE13,'Raw Data'!BG13) -> 0.070222222 | S15: =Q15-R15 -> -0.035 | U15: 361 | V15: =(B15-V$1)/V$2 -> 0.87037037 | W15: =(E15-W$1)/W$2 -> 1.7 | X15: =(H15-X$1)/X$2 -> 2.0130268 | Y15: =(K15-Y$1)/Y$2 -> 12 | Z15: =(N15-Z$1)/Z$2 -> #DIV/0! | AA15: =(Q15-AA$1)/AA$2 -> 0.83264746
... A404: 750 | B404: =AVERAGE('Raw Data'!J402,'Raw Data'!AD402,'Raw Data'!AL402,'Raw Data'!AX402) -> 0.01075 | C404: =AVERAGE('Raw Data'!K402,'Raw Data'!AE402,'Raw Data'!AM402,'Raw Data'!AY402) -> 0.011 | D404: =B404-C404 -> -0.00025 | E404: =AVERAGE('Raw Data'!N402,'Raw Data'!AN402,'Raw Data'!AR402,'Raw Data'!AZ402,'Raw Data'!BB402,'Raw Data'!BJ402) -> 0.0053333333 | F404: =AVERAGE('Raw Data'!O402,'Raw Data'!AO402,'Raw Data'!AS402,'Raw Data'!BA402,'Raw Data'!BC402,'Raw Data'!BK402) -> 0.005 | G404: =E404-F404 -> 0.00033333333 | H404: =AVERAGE('Raw Data'!F402,'Raw Data'!R402,'Raw Data'!V402,'Raw Data'!X402,'Raw Data'!Z402,'Raw Data'!AH402,'Raw Data'!AV402,'Raw Data'!BH402,'Raw Data'!BL402) -> -0.001 | I404: =AVERAGE('Raw Data'!G402,'Raw Data'!S402,'Raw Data'!W402,'Raw Data'!Y402,'Raw Data'!AA402,'Raw Data'!AI402,'Raw Data'!AW402,'Raw Data'!BI402,'Raw Data'!BM402) -> 0.0064444444 | J404: =H404-I404 -> -0.0074444444 | K404: =AVERAGE('Raw Data'!H402,'Raw Data'!AJ402,'Raw Data'!AP402) -> 0.0056666667 | L404: =AVERAGE('Raw Data'!I402,'Raw Data'!AK402,'Raw Data'!AQ402) -> 0.0096666667 | M404: =K404-L404 -> -0.004 | N404: =AVERAGE('Raw Data'!P402) -> 0.01 | O404: =AVERAGE('Raw Data'!Q402) -> 0.005 | P404: =N404-O404 -> 0.005 | Q404: =AVERAGE('Raw Data'!B402,'Raw Data'!D402,'Raw Data'!L402,'Raw Data'!T402,'Raw Data'!AB402,'Raw Data'!AF402,'Raw Data'!AT402,'Raw Data'!BD402,'Raw Data'!BF402) -> 0.0014444444 | R404: =AVERAGE('Raw Data'!C402,'Raw Data'!E402,'Raw Data'!M402,'Raw Data'!U402,'Raw Data'!AC402,'Raw Data'!AG402,'Raw Data'!AU402,'Raw Data'!BE402,'Raw Data'!BG402) -> -0.0021111111 | S404: =Q404-R404 -> 0.0035555556 | U404: 750 | V404: =(B404-V$1)/V$2 -> 0.35185185 | W404: =(E404-W$1)/W$2 -> 0.39047619 | X404: =(H404-X$1)/X$2 -> -0.11724138 | Y404: =(K404-Y$1)/Y$2 -> 1.4444444 | Z404: =(N404-Z$1)/Z$2 -> #DIV/0! | AA404: =(Q404-AA$1)/AA$2 -> -0.0013717421

Sheet Baseline Corrections
E1: 0.0061 | F1: 0.0035 | K1: 0.0027 | L1: 0.0048 | Q1: 0.0005 | R1: 0.005 | W1: 0.002 | X1: 0.007 | AC1: 0.0025 | AD1: 0.0035 | AI1: 0.0005
B2: VS | H2: SWS | N2: MWS | T2: LWS | Z2: DC | AF2: RH1
A3: wl | B3: Sample | C3: Bleach | D3: Difference | E3: Sample | F3: Bleach | G3: Difference | H3: Sample | I3: Bleach | J3: Difference | K3: Sample | L3: Bleach | M3: Difference | N3: Sample | O3: Bleach | P3: Difference | Q3: Sample | R3: Bleach | S3: Difference | T3: Sample | U3: Bleach | V3: Difference | W3: Sample | X3: Bleach | Y3: Difference | Z3: Sample | AA3: Bleach | AB3: Difference | AC3: Sample | AD3: Bleach | AE3: Difference | AF3: Sample | AG3: Bleach | AH3: Difference | AI3: Sample | AJ3: Bleach | AK3: Difference
A4: 350 | B4: =AVERAGE('Raw Data'!J2,'Raw Data'!AD2,'Raw Data'!AL2,'Raw Data'!AX2) -> 0.02525 | C4: =AVERAGE('Raw Data'!K2,'Raw Data'!AE2,'Raw Data'!AM2,'Raw Data'!AY2) -> 0.00975 | D4: =B4-C4 -> 0.0155 | E4: =B4-E$1 -> 0.01915 | F4: =C4-F$1 -> 0.00625 | G4: =E4-F4 -> 0.0129 | H4: =AVERAGE('Raw Data'!N2,'Raw Data'!AN2,'Raw Data'!AR2,'Raw Data'!AZ2,'Raw Data'!BB2,'Raw Data'!BJ2) -> 0.016 | I4: =AVERAGE('Raw Data'!O2,'Raw Data'!AO2,'Raw Data'!AS2,'Raw Data'!BA2,'Raw Data'!BC2,'Raw Data'!BK2) -> 0.0175 | J4: =H4-I4 -> -0.0015 | K4: =H4-K$1 -> 0.0133 | L4: =I4-L$1 -> 0.0127 | M4: =K4-L4 -> 0.0006 | N4: =AVERAGE('Raw Data'!F2,'Raw Data'!R2,'Raw Data'!V2,'Raw Data'!X2,'Raw Data'!Z2,'Raw Data'!AH2,'Raw Data'!AV2,'Raw Data'!BH2,'Raw Data'!BL2) -> 0.034444444 | O4: =AVERAGE('Raw Data'!G2,'Raw Data'!S2,'Raw Data'!W2,'Raw Data'!Y2,'Raw Data'!AA2,'Raw Data'!AI2,'Raw Data'!AW2,'Raw Data'!BI2,'Raw Data'!BM2) -> 0.039555556 | P4: =N4-O4 -> -0.0051111111 | Q4: =N4-Q$1 -> 0.033944444 | R4: =O4-R$1 -> 0.034555556 | S4: =Q4-R4 -> -0.00061111111 | T4: =AVERAGE('Raw Data'!H2,'Raw Data'!AJ2,'Raw Data'!AP2) -> 0.026666667 | U4: =AVERAGE('Raw Data'!I2,'Raw Data'!AK2,'Raw Data'!AQ2) -> -0.01 | V4: =T4-U4 -> 0.036666667 | W4: =T4-W$1 -> 0.024666667 | X4: =U4-X$1 -> -0.017 | Y4: =W4-X4 -> 0.041666667 | Z4: =AVERAGE('Raw Data'!P2) -> 0.027 | AA4: =AVERAGE('Raw Data'!Q2) -> 0.056 | AB4: =Z4-AA4 -> -0.029 | AC4: =Z4-AC$1 -> 0.0245 | AD4: =AA4-AD$1 -> 0.0525 | AE4: =AD4-AC4 -> 0.028 | AF4: =AVERAGE('Raw Data'!B2,'Raw Data'!D2,'Raw Data'!L2,'Raw Data'!T2,'Raw Data'!AB2,'Raw Data'!AF2,'Raw Data'!AT2,'Raw Data'!BD2,'Raw Data'!BF2) -> 0.041222222 | AG4: =AVERAGE('Raw Data'!C2,'Raw Data'!E2,'Raw Data'!M2,'Raw Data'!U2,'Raw Data'!AC2,'Raw Data'!AG2,'Raw Data'!AU2,'Raw Data'!BE2,'Raw Data'!BG2) -> 0.070777778 | AH4: =AF4-AG4 -> -0.029555556 | AI4: =AF4-AI$1 -> 0.040722222 | AJ4: =AG4-AJ$1 -> 0.070777778 | AK4: =AI4-AJ4 -> -0.030055556
A5: 351 | B5: =AVERAGE('Raw Data'!J3,'Raw Data'!AD3,'Raw Data'!AL3,'Raw Data'!AX3) -> 0.02475 | C5: =AVERAGE('Raw Data'!K3,'Raw Data'!AE3,'Raw Data'!AM3,'Raw Data'!AY3) -> 0.00875 | D5: =B5-C5 -> 0.016 | E5: =B5-E$1 -> 0.01865 | F5: =C5-F$1 -> 0.00525 | G5: =D5-G$1 -> 0.016 | H5: =AVERAGE('Raw Data'!N3,'Raw Data'!AN3,'Raw Data'!AR3,'Raw Data'!AZ3,'Raw Data'!BB3,'Raw Data'!BJ3) -> 0.009 | I5: =AVERAGE('Raw Data'!O3,'Raw Data'!AO3,'Raw Data'!AS3,'Raw Data'!BA3,'Raw Data'!BC3,'Raw Data'!BK3) -> 0.016 | J5: =H5-I5 -> -0.007 | K5: =H5-K$1 -> 0.0063 | L5: =I5-L$1 -> 0.0112 | M5: =K5-L5 -> -0.0049 | N5: =AVERAGE('Raw Data'!F3,'Raw Data'!R3,'Raw Data'!V3,'Raw Data'!X3,'Raw Data'!Z3,'Raw Data'!AH3,'Raw Data'!AV3,'Raw Data'!BH3,'Raw Data'!BL3) -> 0.031444444 | O5: =AVERAGE('Raw Data'!G3,'Raw Data'!S3,'Raw Data'!W3,'Raw Data'!Y3,'Raw Data'!AA3,'Raw Data'!AI3,'Raw Data'!AW3,'Raw Data'!BI3,'Raw Data'!BM3) -> 0.035222222 | P5: =N5-O5 -> -0.0037777778 | Q5: =N5-Q$1 -> 0.030944444 | R5: =O5-R$1 -> 0.030222222 | S5: =Q5-R5 -> 0.00072222222 | T5: =AVERAGE('Raw Data'!H3,'Raw Data'!AJ3,'Raw Data'!AP3) -> 0.03 | U5: =AVERAGE('Raw Data'!I3,'Raw Data'!AK3,'Raw Data'!AQ3) -> -0.0093333333 | V5: =T5-U5 -> 0.039333333 | W5: =T5-W$1 -> 0.028 | X5: =U5-X$1 -> -0.016333333 | Y5: =W5-X5 -> 0.044333333 | Z5: =AVERAGE('Raw Data'!P3) -> 0.015 | AA5: =AVERAGE('Raw Data'!Q3) -> 0.045 | AB5: =Z5-AA5 -> -0.03 | AC5: =Z5-AC$1 -> 0.0125 | AD5: =AA5-AD$1 -> 0.0415 | AE5: =AC5-AD5 -> -0.029 | AF5: =AVERAGE('Raw Data'!B3,'Raw Data'!D3,'Raw Data'!L3,'Raw Data'!T3,'Raw Data'!AB3,'Raw Data'!AF3,'Raw Data'!AT3,'Raw Data'!BD3,'Raw Data'!BF3) -> 0.043555556 | AG5: =AVERAGE('Raw Data'!C3,'Raw Data'!E3,'Raw Data'!M3,'Raw Data'!U3,'Raw Data'!AC3,'Raw Data'!AG3,'Raw Data'!AU3,'Raw Data'!BE3,'Raw Data'!BG3) -> 0.073111111 | AH5: =AF5-AG5 -> -0.029555556 | AI5: =AF5-AI$1 -> 0.043055556 | AJ5: =AG5-AJ$1 -> 0.073111111 | AK5: =AI5-AJ5 -> -0.030055556
A6: 352 | B6: =AVERAGE('Raw Data'!J4,'Raw Data'!AD4,'Raw Data'!AL4,'Raw Data'!AX4) -> 0.01875 | C6: =AVERAGE('Raw Data'!K4,'Raw Data'!AE4,'Raw Data'!AM4,'Raw Data'!AY4) -> 0.00875 | D6: =B6-C6 -> 0.01 | E6: =B6-E$1 -> 0.01265 | F6: =C6-F$1 -> 0.00525 | G6: =D6-G$1 -> 0.01 | H6: =AVERAGE('Raw Data'!N4,'Raw Data'!AN4,'Raw Data'!AR4,'Raw Data'!AZ4,'Raw Data'!BB4,'Raw Data'!BJ4) -> 0.0115 | I6: =AVERAGE('Raw Data'!O4,'Raw Data'!AO4,'Raw Data'!AS4,'Raw Data'!BA4,'Raw Data'!BC4,'Raw Data'!BK4) -> 0.0165 | J6: =H6-I6 -> -0.005 | K6: =H6-K$1 -> 0.0088 | L6: =I6-L$1 -> 0.0117 | M6: =K6-L6 -> -0.0029 | N6: =AVERAGE('Raw Data'!F4,'Raw Data'!R4,'Raw Data'!V4,'Raw Data'!X4,'Raw Data'!Z4,'Raw Data'!AH4,'Raw Data'!AV4,'Raw Data'!BH4,'Raw Data'!BL4) -> 0.032 | O6: =AVERAGE('Raw Data'!G4,'Raw Data'!S4,'Raw Data'!W4,'Raw Data'!Y4,'Raw Data'!AA4,'Raw Data'!AI4,'Raw Data'!AW4,'Raw Data'!BI4,'Raw Data'!BM4) -> 0.033666667 | P6: =N6-O6 -> -0.0016666667 | Q6: =N6-Q$1 -> 0.0315 | R6: =O6-R$1 -> 0.028666667 | S6: =Q6-R6 -> 0.0028333333 | T6: =AVERAGE('Raw Data'!H4,'Raw Data'!AJ4,'Raw Data'!AP4) -> 0.027 | U6: =AVERAGE('Raw Data'!I4,'Raw Data'!AK4,'Raw Data'!AQ4) -> -0.01 | V6: =T6-U6 -> 0.037 | W6: =T6-W$1 -> 0.025 | X6: =U6-X$1 -> -0.017 | Y6: =W6-X6 -> 0.042 | Z6: =AVERAGE('Raw Data'!P4) -> 0.007 | AA6: =AVERAGE('Raw Data'!Q4) -> 0.041 | AB6: =Z6-AA6 -> -0.034 | AC6: =Z6-AC$1 -> 0.0045 | AD6: =AA6-AD$1 -> 0.0375 | AE6: =AC6-AD6 -> -0.033 | AF6: =AVERAGE('Raw Data'!B4,'Raw Data'!D4,'Raw Data'!L4,'Raw Data'!T4,'Raw Data'!AB4,'Raw Data'!AF4,'Raw Data'!AT4,'Raw Data'!BD4,'Raw Data'!BF4) -> 0.040222222 | AG6: =AVERAGE('Raw Data'!C4,'Raw Data'!E4,'Raw Data'!M4,'Raw Data'!U4,'Raw Data'!AC4,'Raw Data'!AG4,'Raw Data'!AU4,'Raw Data'!BE4,'Raw Data'!BG4) -> 0.068888889 | AH6: =AF6-AG6 -> -0.028666667 | AI6: =AF6-AI$1 -> 0.039722222 | AJ6: =AG6-AJ$1 -> 0.068888889 | AK6: =AI6-AJ6 -> -0.029166667
A7: 353 | B7: =AVERAGE('Raw Data'!J5,'Raw Data'!AD5,'Raw Data'!AL5,'Raw Data'!AX5) -> 0.01875 | C7: =AVERAGE('Raw Data'!K5,'Raw Data'!AE5,'Raw Data'!AM5,'Raw Data'!AY5) -> 0.0115 | D7: =B7-C7 -> 0.00725 | E7: =B7-E$1 -> 0.01265 | F7: =C7-F$1 -> 0.008 | G7: =D7-G$1 -> 0.00725 | H7: =AVERAGE('Raw Data'!N5,'Raw Data'!AN5,'Raw Data'!AR5,'Raw Data'!AZ5,'Raw Data'!BB5,'Raw Data'!BJ5) -> 0.018166667 | I7: =AVERAGE('Raw Data'!O5,'Raw Data'!AO5,'Raw Data'!AS5,'Raw Data'!BA5,'Raw Data'!BC5,'Raw Data'!BK5) -> 0.017666667 | J7: =H7-I7 -> 0.0005 | K7: =H7-K$1 -> 0.015466667 | L7: =I7-L$1 -> 0.012866667 | M7: =K7-L7 -> 0.0026 | N7: =AVERAGE('Raw Data'!F5,'Raw Data'!R5,'Raw Data'!V5,'Raw Data'!X5,'Raw Data'!Z5,'Raw Data'!AH5,'Raw Data'!AV5,'Raw Data'!BH5,'Raw Data'!BL5) -> 0.033222222 | O7: =AVERAGE('Raw Data'!G5,'Raw Data'!S5,'Raw Data'!W5,'Raw Data'!Y5,'Raw Data'!AA5,'Raw Data'!AI5,'Raw Data'!AW5,'Raw Data'!BI5,'Raw Data'!BM5) -> 0.037444444 | P7: =N7-O7 -> -0.0042222222 | Q7: =N7-Q$1 -> 0.032722222 | R7: =O7-R$1 -> 0.032444444 | S7: =Q7-R7 -> 0.00027777778 | T7: =AVERAGE('Raw Data'!H5,'Raw Data'!AJ5,'Raw Data'!AP5) -> 0.028666667 | U7: =AVERAGE('Raw Data'!I5,'Raw Data'!AK5,'Raw Data'!AQ5) -> -0.014666667 | V7: =T7-U7 -> 0.043333333 | W7: =T7-W$1 -> 0.026666667 | X7: =U7-X$1 -> -0.021666667 | Y7: =W7-X7 -> 0.048333333 | Z7: =AVERAGE('Raw Data'!P5) -> 0.014 | AA7: =AVERAGE('Raw Data'!Q5) -> 0.046 | AB7: =Z7-AA7 -> -0.032 | AC7: =Z7-AC$1 -> 0.0115 | AD7: =AA7-AD$1 -> 0.0425 | AE7: =AC7-AD7 -> -0.031 | AF7: =AVERAGE('Raw Data'!B5,'Raw Data'!D5,'Raw Data'!L5,'Raw Data'!T5,'Raw Data'!AB5,'Raw Data'!AF5,'Raw Data'!AT5,'Raw Data'!BD5,'Raw Data'!BF5) -> 0.041666667 | AG7: =AVERAGE('Raw Data'!C5,'Raw Data'!E5,'Raw Data'!M5,'Raw Data'!U5,'Raw Data'!AC5,'Raw Data'!AG5,'Raw Data'!AU5,'Raw Data'!BE5,'Raw Data'!BG5) -> 0.072666667 | AH7: =AF7-AG7 -> -0.031 | AI7: =AF7-AI$1 -> 0.041166667 | AJ7: =AG7-AJ$1 -> 0.072666667 | AK7: =AI7-AJ7 -> -0.0315
A8: 354 | B8: =AVERAGE('Raw Data'!J6,'Raw Data'!AD6,'Raw Data'!AL6,'Raw Data'!AX6) -> 0.019 | C8: =AVERAGE('Raw Data'!K6,'Raw Data'!AE6,'Raw Data'!AM6,'Raw Data'!AY6) -> 0.0105 | D8: =B8-C8 -> 0.0085 | E8: =B8-E$1 -> 0.0129 | F8: =C8-F$1 -> 0.007 | G8: =D8-G$1 -> 0.0085 | H8: =AVERAGE('Raw Data'!N6,'Raw Data'!AN6,'Raw Data'!AR6,'Raw Data'!AZ6,'Raw Data'!BB6,'Raw Data'!BJ6) -> 0.019666667 | I8: =AVERAGE('Raw Data'!O6,'Raw Data'!AO6,'Raw Data'!AS6,'Raw Data'!BA6,'Raw Data'!BC6,'Raw Data'!BK6) -> 0.0195 | J8: =H8-I8 -> 0.00016666667 | K8: =H8-K$1 -> 0.016966667 | L8: =I8-L$1 -> 0.0147 | M8: =K8-L8 -> 0.0022666667 | N8: =AVERAGE('Raw Data'!F6,'Raw Data'!R6,'Raw Data'!V6,'Raw Data'!X6,'Raw Data'!Z6,'Raw Data'!AH6,'Raw Data'!AV6,'Raw Data'!BH6,'Raw Data'!BL6) -> 0.033666667 | O8: =AVERAGE('Raw Data'!G6,'Raw Data'!S6,'Raw Data'!W6,'Raw Data'!Y6,'Raw Data'!AA6,'Raw Data'!AI6,'Raw Data'!AW6,'Raw Data'!BI6,'Raw Data'!BM6) -> 0.035555556 | P8: =N8-O8 -> -0.0018888889 | Q8: =N8-Q$1 -> 0.033166667 | R8: =O8-R$1 -> 0.030555556 | S8: =Q8-R8 -> 0.0026111111 | T8: =AVERAGE('Raw Data'!H6,'Raw Data'!AJ6,'Raw Data'!AP6) -> 0.035666667 | U8: =AVERAGE('Raw Data'!I6,'Raw Data'!AK6,'Raw Data'!AQ6) -> -0.0073333333 | V8: =T8-U8 -> 0.043 | W8: =T8-W$1 -> 0.033666667 | X8: =U8-X$1 -> -0.014333333 | Y8: =W8-X8 -> 0.048 | Z8: =AVERAGE('Raw Data'!P6) -> 0.013 | AA8: =AVERAGE('Raw Data'!Q6) -> 0.042 | AB8: =Z8-AA8 -> -0.029 | AC8: =Z8-AC$1 -> 0.0105 | AD8: =AA8-AD$1 -> 0.0385 | AE8: =AC8-AD8 -> -0.028 | AF8: =AVERAGE('Raw Data'!B6,'Raw Data'!D6,'Raw Data'!L6,'Raw Data'!T6,'Raw Data'!AB6,'Raw Data'!AF6,'Raw Data'!AT6,'Raw Data'!BD6,'Raw Data'!BF6) -> 0.042888889 | AG8: =AVERAGE('Raw Data'!C6,'Raw Data'!E6,'Raw Data'!M6,'Raw Data'!U6,'Raw Data'!AC6,'Raw Data'!AG6,'Raw Data'!AU6,'Raw Data'!BE6,'Raw Data'!BG6) -> 0.075111111 | AH8: =AF8-AG8 -> -0.032222222 | AI8: =AF8-AI$1 -> 0.042388889 | AJ8: =AG8-AJ$1 -> 0.075111111 | AK8: =AI8-AJ8 -> -0.032722222
A9: 355 | B9: =AVERAGE('Raw Data'!J7,'Raw Data'!AD7,'Raw Data'!AL7,'Raw Data'!AX7) -> 0.02575 | C9: =AVERAGE('Raw Data'!K7,'Raw Data'!AE7,'Raw Data'!AM7,'Raw Data'!AY7) -> 0.01525 | D9: =B9-C9 -> 0.0105 | E9: =B9-E$1 -> 0.01965 | F9: =C9-F$1 -> 0.01175 | G9: =D9-G$1 -> 0.0105 | H9: =AVERAGE('Raw Data'!N7,'Raw Data'!AN7,'Raw Data'!AR7,'Raw Data'!AZ7,'Raw Data'!BB7,'Raw Data'!BJ7) -> 0.015666667 | I9: =AVERAGE('Raw Data'!O7,'Raw Data'!AO7,'Raw Data'!AS7,'Raw Data'!BA7,'Raw Data'!BC7,'Raw Data'!BK7) -> 0.018666667 | J9: =H9-I9 -> -0.003 | K9: =H9-K$1 -> 0.012966667 | L9: =I9-L$1 -> 0.013866667 | M9: =K9-L9 -> -0.0009 | N9: =AVERAGE('Raw Data'!F7,'Raw Data'!R7,'Raw Data'!V7,'Raw Data'!X7,'Raw Data'!Z7,'Raw Data'!AH7,'Raw Data'!AV7,'Raw Data'!BH7,'Raw Data'!BL7) -> 0.032888889 | O9: =AVERAGE('Raw Data'!G7,'Raw Data'!S7,'Raw Data'!W7,'Raw Data'!Y7,'Raw Data'!AA7,'Raw Data'!AI7,'Raw Data'!AW7,'Raw Data'!BI7,'Raw Data'!BM7) -> 0.037 | P9: =N9-O9 -> -0.0041111111 | Q9: =N9-Q$1 -> 0.032388889 | R9: =O9-R$1 -> 0.032 | S9: =Q9-R9 -> 0.00038888889 | T9: =AVERAGE('Raw Data'!H7,'Raw Data'!AJ7,'Raw Data'!AP7) -> 0.036666667 | U9: =AVERAGE('Raw Data'!I7,'Raw Data'!AK7,'Raw Data'!AQ7) -> 0.003 | V9: =T9-U9 -> 0.033666667 | W9: =T9-W$1 -> 0.034666667 | X9: =U9-X$1 -> -0.004 | Y9: =W9-X9 -> 0.038666667 | Z9: =AVERAGE('Raw Data'!P7) -> 0.014 | AA9: =AVERAGE('Raw Data'!Q7) -> 0.045 | AB9: =Z9-AA9 -> -0.031 | AC9: =Z9-AC$1 -> 0.0115 | AD9: =AA9-AD$1 -> 0.0415 | AE9: =AC9-AD9 -> -0.03 | AF9: =AVERAGE('Raw Data'!B7,'Raw Data'!D7,'Raw Data'!L7,'Raw Data'!T7,'Raw Data'!AB7,'Raw Data'!AF7,'Raw Data'!AT7,'Raw Data'!BD7,'Raw Data'!BF7) -> 0.042666667 | AG9: =AVERAGE('Raw Data'!C7,'Raw Data'!E7,'Raw Data'!M7,'Raw Data'!U7,'Raw Data'!AC7,'Raw Data'!AG7,'Raw Data'!AU7,'Raw Data'!BE7,'Raw Data'!BG7) -> 0.075222222 | AH9: =AF9-AG9 -> -0.032555556 | AI9: =AF9-AI$1 -> 0.042166667 | AJ9: =AG9-AJ$1 -> 0.075222222 | AK9: =AI9-AJ9 -> -0.033055556
A10: 356 | B10: =AVERAGE('Raw Data'!J8,'Raw Data'!AD8,'Raw Data'!AL8,'Raw Data'!AX8) -> 0.025 | C10: =AVERAGE('Raw Data'!K8,'Raw Data'!AE8,'Raw Data'!AM8,'Raw Data'!AY8) -> 0.01325 | D10: =B10-C10 -> 0.01175 | E10: =B10-E$1 -> 0.0189 | F10: =C10-F$1 -> 0.00975 | G10: =D10-G$1 -> 0.01175 | H10: =AVERAGE('Raw Data'!N8,'Raw Data'!AN8,'Raw Data'!AR8,'Raw Data'!AZ8,'Raw Data'!BB8,'Raw Data'!BJ8) -> 0.0185 | I10: =AVERAGE('Raw Data'!O8,'Raw Data'!AO8,'Raw Data'!AS8,'Raw Data'!BA8,'Raw Data'!BC8,'Raw Data'!BK8) -> 0.020333333 | J10: =H10-I10 -> -0.0018333333 | K10: =H10-K$1 -> 0.0158 | L10: =I10-L$1 -> 0.015533333 | M10: =K10-L10 -> 0.00026666667 | N10: =AVERAGE('Raw Data'!F8,'Raw Data'!R8,'Raw Data'!V8,'Raw Data'!X8,'Raw Data'!Z8,'Raw Data'!AH8,'Raw Data'!AV8,'Raw Data'!BH8,'Raw Data'!BL8) -> 0.029222222 | O10: =AVERAGE('Raw Data'!G8,'Raw Data'!S8,'Raw Data'!W8,'Raw Data'!Y8,'Raw Data'!AA8,'Raw Data'!AI8,'Raw Data'!AW8,'Raw Data'!BI8,'Raw Data'!BM8) -> 0.031444444 | P10: =N10-O10 -> -0.0022222222 | Q10: =N10-Q$1 -> 0.028722222 | R10: =O10-R$1 -> 0.026444444 | S10: =Q10-R10 -> 0.0022777778 | T10: =AVERAGE('Raw Data'!H8,'Raw Data'!AJ8,'Raw Data'!AP8) -> 0.031333333 | U10: =AVERAGE('Raw Data'!I8,'Raw Data'!AK8,'Raw Data'!AQ8) -> 0.0023333333 | V10: =T10-U10 -> 0.029 | W10: =T10-W$1 -> 0.029333333 | X10: =U10-X$1 -> -0.0046666667 | Y10: =W10-X10 -> 0.034 | Z10: =AVERAGE('Raw Data'!P8) -> 0.013 | AA10: =AVERAGE('Raw Data'!Q8) -> 0.048 | AB10: =Z10-AA10 -> -0.035 | AC10: =Z10-AC$1 -> 0.0105 | AD10: =AA10-AD$1 -> 0.0445 | AE10: =AC10-AD10 -> -0.034 | AF10: =AVERAGE('Raw Data'!B8,'Raw Data'!D8,'Raw Data'!L8,'Raw Data'!T8,'Raw Data'!AB8,'Raw Data'!AF8,'Raw Data'!AT8,'Raw Data'!BD8,'Raw Data'!BF8) -> 0.042444444 | AG10: =AVERAGE('Raw Data'!C8,'Raw Data'!E8,'Raw Data'!M8,'Raw Data'!U8,'Raw Data'!AC8,'Raw Data'!AG8,'Raw Data'!AU8,'Raw Data'!BE8,'Raw Data'!BG8) -> 0.072444444 | AH10: =AF10-AG10 -> -0.03 | AI10: =AF10-AI$1 -> 0.041944444 | AJ10: =AG10-AJ$1 -> 0.072444444 | AK10: =AI10-AJ10 -> -0.0305
A11: 357 | B11: =AVERAGE('Raw Data'!J9,'Raw Data'!AD9,'Raw Data'!AL9,'Raw Data'!AX9) -> 0.02275 | C11: =AVERAGE('Raw Data'!K9,'Raw Data'!AE9,'Raw Data'!AM9,'Raw Data'!AY9) -> 0.01075 | D11: =B11-C11 -> 0.012 | E11: =B11-E$1 -> 0.01665 | F11: =C11-F$1 -> 0.00725 | G11: =D11-G$1 -> 0.012 | H11: =AVERAGE('Raw Data'!N9,'Raw Data'!AN9,'Raw Data'!AR9,'Raw Data'!AZ9,'Raw Data'!BB9,'Raw Data'!BJ9) -> 0.016166667 | I11: =AVERAGE('Raw Data'!O9,'Raw Data'!AO9,'Raw Data'!AS9,'Raw Data'!BA9,'Raw Data'!BC9,'Raw Data'!BK9) -> 0.018833333 | J11: =H11-I11 -> -0.0026666667 | K11: =H11-K$1 -> 0.013466667 | L11: =I11-L$1 -> 0.014033333 | M11: =K11-L11 -> -0.00056666667 | N11: =AVERAGE('Raw Data'!F9,'Raw Data'!R9,'Raw Data'!V9,'Raw Data'!X9,'Raw Data'!Z9,'Raw Data'!AH9,'Raw Data'!AV9,'Raw Data'!BH9,'Raw Data'!BL9) -> 0.031222222 | O11: =AVERAGE('Raw Data'!G9,'Raw Data'!S9,'Raw Data'!W9,'Raw Data'!Y9,'Raw Data'!AA9,'Raw Data'!AI9,'Raw Data'!AW9,'Raw Data'!BI9,'Raw Data'!BM9) -> 0.033333333 | P11: =N11-O11 -> -0.0021111111 | Q11: =N11-Q$1 -> 0.030722222 | R11: =O11-R$1 -> 0.028333333 | S11: =Q11-R11 -> 0.0023888889 | T11: =AVERAGE('Raw Data'!H9,'Raw Data'!AJ9,'Raw Data'!AP9) -> 0.031 | U11: =AVERAGE('Raw Data'!I9,'Raw Data'!AK9,'Raw Data'!AQ9) -> 0.0016666667 | V11: =T11-U11 -> 0.029333333 | W11: =T11-W$1 -> 0.029 | X11: =U11-X$1 -> -0.0053333333 | Y11: =W11-X11 -> 0.034333333 | Z11: =AVERAGE('Raw Data'!P9) -> 0.022 | AA11: =AVERAGE('Raw Data'!Q9) -> 0.053 | AB11: =Z11-AA11 -> -0.031 | AC11: =Z11-AC$1 -> 0.0195 | AD11: =AA11-AD$1 -> 0.0495 | AE11: =AC11-AD11 -> -0.03 | AF11: =AVERAGE('Raw Data'!B9,'Raw Data'!D9,'Raw Data'!L9,'Raw Data'!T9,'Raw Data'!AB9,'Raw Data'!AF9,'Raw Data'!AT9,'Raw Data'!BD9,'Raw Data'!BF9) -> 0.042222222 | AG11: =AVERAGE('Raw Data'!C9,'Raw Data'!E9,'Raw Data'!M9,'Raw Data'!U9,'Raw Data'!AC9,'Raw Data'!AG9,'Raw Data'!AU9,'Raw Data'!BE9,'Raw Data'!BG9) -> 0.071555556 | AH11: =AF11-AG11 -> -0.029333333 | AI11: =AF11-AI$1 -> 0.041722222 | AJ11: =AG11-AJ$1 -> 0.071555556 | AK11: =AI11-AJ11 -> -0.029833333
A12: 358 | B12: =AVERAGE('Raw Data'!J10,'Raw Data'!AD10,'Raw Data'!AL10,'Raw Data'!AX10) -> 0.025 | C12: =AVERAGE('Raw Data'!K10,'Raw Data'!AE10,'Raw Data'!AM10,'Raw Data'!AY10) -> 0.013 | D12: =B12-C12 -> 0.012 | E12: =B12-E$1 -> 0.0189 | F12: =C12-F$1 -> 0.0095 | G12: =D12-G$1 -> 0.012 | H12: =AVERAGE('Raw Data'!N10,'Raw Data'!AN10,'Raw Data'!AR10,'Raw Data'!AZ10,'Raw Data'!BB10,'Raw Data'!BJ10) -> 0.0105 | I12: =AVERAGE('Raw Data'!O10,'Raw Data'!AO10,'Raw Data'!AS10,'Raw Data'!BA10,'Raw Data'!BC10,'Raw Data'!BK10) -> 0.0155 | J12: =H12-I12 -> -0.005 | K12: =H12-K$1 -> 0.0078 | L12: =I12-L$1 -> 0.0107 | M12: =K12-L12 -> -0.0029 | N12: =AVERAGE('Raw Data'!F10,'Raw Data'!R10,'Raw Data'!V10,'Raw Data'!X10,'Raw Data'!Z10,'Raw Data'!AH10,'Raw Data'!AV10,'Raw Data'!BH10,'Raw Data'!BL10) -> 0.026555556 | O12: =AVERAGE('Raw Data'!G10,'Raw Data'!S10,'Raw Data'!W10,'Raw Data'!Y10,'Raw Data'!AA10,'Raw Data'!AI10,'Raw Data'!AW10,'Raw Data'!BI10,'Raw Data'!BM10) -> 0.030888889 | P12: =N12-O12 -> -0.0043333333 | Q12: =N12-Q$1 -> 0.026055556 | R12: =O12-R$1 -> 0.025888889 | S12: =Q12-R12 -> 0.00016666667 | T12: =AVERAGE('Raw Data'!H10,'Raw Data'!AJ10,'Raw Data'!AP10) -> 0.032 | U12: =AVERAGE('Raw Data'!I10,'Raw Data'!AK10,'Raw Data'!AQ10) -> 1.4456029e-18 | V12: =T12-U12 -> 0.032 | W12: =T12-W$1 -> 0.03 | X12: =U12-X$1 -> -0.007 | Y12: =W12-X12 -> 0.037 | Z12: =AVERAGE('Raw Data'!P10) -> 0.015 | AA12: =AVERAGE('Raw Data'!Q10) -> 0.044 | AB12: =Z12-AA12 -> -0.029 | AC12: =Z12-AC$1 -> 0.0125 | AD12: =AA12-AD$1 -> 0.0405 | AE12: =AC12-AD12 -> -0.028 | AF12: =AVERAGE('Raw Data'!B10,'Raw Data'!D10,'Raw Data'!L10,'Raw Data'!T10,'Raw Data'!AB10,'Raw Data'!AF10,'Raw Data'!AT10,'Raw Data'!BD10,'Raw Data'!BF10) -> 0.038555556 | AG12: =AVERAGE('Raw Data'!C10,'Raw Data'!E10,'Raw Data'!M10,'Raw Data'!U10,'Raw Data'!AC10,'Raw Data'!AG10,'Raw Data'!AU10,'Raw Data'!BE10,'Raw Data'!BG10) -> 0.069666667 | AH12: =AF12-AG12 -> -0.031111111 | AI12: =AF12-AI$1 -> 0.038055556 | AJ12: =AG12-AJ$1 -> 0.069666667 | AK12: =AI12-AJ12 -> -0.031611111
