Workbook

Sheet HAGO101
A1: Species | B1: Hawaiian Goose | C1: Hawaiian Goose | D1: Hawaiian Goose | E1: Hawaiian Goose | F1: Hawaiian Goose | G1: Hawaiian Goose | H1: Hawaiian Goose | I1: Hawaiian Goose | J1: Hawaiian Goose | K1: Hawaiian Goose | L1: Hawaiian Goose | M1: Hawaiian Goose | N1: Hawaiian Goose | O1: Hawaiian Goose | P1: Hawaiian Goose | Q1: Hawaiian Goose | R1: Hawaiian Goose | S1: Hawaiian Goose | T1: Hawaiian Goose | U1: Hawaiian Goose | V1: Hawaiian Goose | W1: Hawaiian Goose | X1: Hawaiian Goose | Y1: Hawaiian Goose | Z1: Hawaiian Goose | AA1: Hawaiian Goose | AB1: Hawaiian Goose | AC1: Hawaiian Goose | AD1: Hawaiian Goose | AE1: Hawaiian Goose | AF1: Hawaiian Goose | AG1: Hawaiian Goose | AH1: Hawaiian Goose | AI1: Hawaiian Goose
A2: Bird ID | B2: RE | C2: RE | D2: RE | E2: RE | F2: RE | G2: RE | H2: RE | I2: RE | J2: RE | K2: RE | L2: RE | M2: RE | N2: RE | O2: RE | P2: RE | Q2: RE | R2: RE | S2: RE | T2: RE | U2: RE | V2: RE | W2: RE | X2: RE | Y2: RE | Z2: RE | AA2: RE | AB2: RE | AC2: RE | AD2: RE | AE2: RE | AF2: RE | AG2: RE | AH2: RE | AI2: RE
A3: Prep # | B3: 1 | C3: 1 | D3: 1 | E3: 1 | F3: 1 | G3: 1 | H3: 1 | I3: 1 | J3: 1 | K3: 1 | L3: 1 | M3: 1 | N3: 1 | O3: 1 | P3: 1 | Q3: 1 | R3: 2 | S3: 2 | T3: 2 | U3: 2 | V3: 2 | W3: 2 | X3: 2 | Y3: 2 | Z3: 3 | AA3: 3 | AB3: 3 | AC3: 3 | AD3: 3 | AE3: 3 | AF3: 3 | AG3: 4 | AH3: 4 | AI3: 4
A4: Age | B4: AD | C4: AD | D4: AD | E4: AD | F4: AD | G4: AD | H4: AD | I4: AD | J4: AD | K4: AD | L4: AD | M4: AD | N4: AD | O4: AD | P4: AD | Q4: AD | R4: AD | S4: AD | T4: AD | U4: AD | V4: AD | W4: AD | X4: AD | Y4: AD | Z4: AD | AA4: AD | AB4: AD | AC4: AD | AD4: AD | AE4: AD | AF4: AD | AG4: AD | AH4: AD | AI4: AD
A5: Cellular Component | B5: O | C5: O | D5: O | E5: O | F5: O | G5: O | H5: O | I5: O | J5: O | K5: O | L5: C | M5: O | N5: O | O5: O | P5: O | Q5: O | R5: O | S5: O | T5: O | U5: O | V5: O | W5: O | X5: O | Y5: O | Z5: O | AA5: O | AB5: O | AC5: O | AD5: O | AE5: O | AF5: O | AG5: O | AH5: O | AI5: O
A6: Type | B6: I | C6: Y | D6: R | E6: I | F6: B | G6: Y | H6: I | I6: I | J6: Y | K6: Y | L6: B | M6: I | N6: Y | O6: I | P6: Y | Q6: Y | R6: I | S6: I | T6: R | U6: I | V6: I | W6: R | X6: I | Y6: X | Z6: B | AA6: B | AB6: B | AC6: I | AD6: B | AE6: R | AF6: R | AG6: R | AH6: I | AI6: I
A7: Lambda Mid | B7: 519.6 | C7: 533.6 | D7: 593.3 | E7: 521.1 | F7: 455.1 | G7: 533.7 | H7: 507 | I7: 513.7 | J7: 518.4 | K7: 531.9 | L7: 508.2 | M7: 462.9 | N7: 529.8 | O7: 515.4 | P7: 533.3 | Q7: 532.9 | R7: 519.1 | S7: 519.3 | T7: 587.8 | U7: 517.3 | V7: 515.6 | W7: 586 | X7: 520.3 | Y7: 522.8 | Z7: 447.4 | AA7: 456.1 | AB7: 454.5 | AC7: 521.8 | AD7: 459.5 | AE7: 590.1 | AF7: 583.1 | AG7: 587.8 | AH7: 465.4 | AI7: 476.5
A8: Lambda Cut | B8: 505.58038 | C8: 521.00936 | D8: 574.14795 | E8: 506.7191 | F8: 434.93564 | G8: 520.19786 | H8: 492.21227 | I8: 500.14672 | J8: 504.82114 | K8: 519.13879 | L8: 482.37704 | M8: 441.83811 | N8: 516.66565 | O8: 501.02496 | P8: 520.1337 | Q8: 520.07365 | R8: 506.06835 | S8: 506.66779 | T8: 569.90761 | U8: 504.6859 | V8: 502.8038 | W8: 567.78781 | X8: 507.20129 | Y8: 509.91283 | Z8: 328.29697 | AA8: 427.6151 | AB8: 422.50746 | AC8: 509.18325 | AD8: 418.50105 | AE8: 571.51934 | AF8: 564.74209 | AG8: 569.6961 | AH8: 445.83892 | AI8: 408.21279
A9: Lambda 0 | B9: 515.9549 | C9: 530.32643 | D9: 588.32047 | E9: 517.36097 | F9: 449.85727 | G9: 530.18944 | H9: 503.15519 | I9: 510.17615 | J9: 514.8695 | K9: 528.58208 | L9: 501.48603 | M9: 457.42391 | N9: 526.38507 | O9: 511.66249 | P9: 529.87676 | Q9: 529.56515 | R9: 515.71177 | S9: 516.01562 | T9: 583.14798 | U9: 514.02033 | V9: 512.27299 | W9: 581.26483 | X9: 516.89433 | Y9: 519.44934 | Z9: 416.43321 | AA9: 448.69393 | AB9: 446.18194 | AC9: 518.51964 | AD9: 448.84027 | AE9: 585.26903 | AF9: 578.32694 | AG9: 583.09299 | AH9: 460.31412 | AI9: 458.74533
A10: b | B10: 0.10306983 | C10: 0.11476776 | D10: 0.075448853 | E10: 0.10048051 | F10: 0.071661097 | G10: 0.1070201 | H10: 0.097716122 | I10: 0.10661628 | J10: 0.10641538 | K10: 0.11323375 | L10: 0.055957961 | M10: 0.068607333 | N10: 0.11001685 | O10: 0.10052145 | P10: 0.10974989 | Q10: 0.11265872 | R10: 0.1108839 | S10: 0.11439008 | T10: 0.080760573 | U10: 0.11455435 | V10: 0.11292413 | W10: 0.079342464 | X10: 0.11031617 | Y10: 0.11212701 | Z10: 0.012132353 | AA10: 0.050728629 | AB10: 0.045166778 | AC10: 0.11453026 | AD10: 0.035244803 | AE10: 0.077769041 | AF10: 0.078712672 | AG10: 0.079817041 | AH10: 0.073871159 | AI10: 0.021160626
A11: Bmid | B11: 0.035664299 | C11: 0.039712029 | D11: 0.026106869 | E11: 0.034768344 | F11: 0.024796227 | G11: 0.037031177 | H11: 0.033811807 | I11: 0.036891448 | J11: 0.036821932 | K11: 0.039181228 | L11: 0.019362616 | M11: 0.023739562 | N11: 0.038068113 | O11: 0.03478251 | P11: 0.03797574 | Q11: 0.038982256 | R11: 0.038368131 | S11: 0.039581341 | T11: 0.027944835 | U11: 0.039638182 | V11: 0.039074094 | W11: 0.02745414 | X11: 0.038171686 | Y11: 0.038798274 | Z11: 0.0041980459 | AA11: 0.017553159 | AB11: 0.015628643 | AC11: 0.039629849 | AD11: 0.012195434 | AE11: 0.026909703 | AF11: 0.027236219 | AG11: 0.027618353 | AH11: 0.025560955 | AI11: 0.0073220159
A12: R Squared | B12: 0.99363908 | C12: 0.98827624 | D12: 0.99230851 | E12: 0.99089002 | F12: 0.80267711 | G12: 0.9883386 | H12: 0.9973362 | I12: 0.9955775 | J12: 0.99517132 | K12: 0.99388575 | L12: 0.91030187 | M12: 0.99794639 | N12: 0.99180324 | O12: 0.99591343 | P12: 0.98816458 | Q12: 0.99239814 | R12: 0.99429513 | S12: 0.99139564 | T12: 0.9933957 | U12: 0.99288771 | V12: 0.99386047 | W12: 0.99624263 | X12: 0.99084855 | Y12: 0.9938077 | Z12: 0.15491072 | AA12: 0.90136816 | AB12: 0.92122578 | AC12: 0.99270354 | AD12: 0.84935712 | AE12: 0.99103518 | AF12: 0.99520314 | AG12: 0.99586984 | AH12: 0.99623752 | AI12: 0.54791604
A13: Intercept | B13: 19.035411 | C13: 21.693663 | D13: 16.007579 | E13: 18.591173 | F13: 11.759301 | G13: 20.30718 | H13: 17.5894 | I13: 19.400968 | J13: 19.522285 | K13: 21.382997 | L13: 10.343236 | M13: 11.506237 | N13: 20.685667 | O13: 18.479751 | P13: 20.684179 | Q13: 21.232018 | R13: 20.477737 | S13: 20.978292 | T13: 16.885205 | U13: 21.017327 | V13: 20.631518 | W13: 16.572207 | X13: 20.423923 | Y13: 20.820087 | Z13: 2.377732 | AA13: 8.515798 | AB13: 7.6054025 | AC13: 21.117 | AD13: 6.1063257 | AE13: 16.36758 | AF13: 16.391576 | AG13: 16.735903 | AH13: 12.396842 | AI13: 3.9870074
A14: Slope | B14: -0.035672688 | C14: -0.039718409 | D14: -0.026138871 | E14: -0.034715827 | F14: -0.024737686 | G14: -0.037115069 | H14: -0.033703751 | I14: -0.03679114 | J14: -0.036690787 | K14: -0.039263098 | L14: -0.019369156 | M14: -0.023778476 | N14: -0.038101366 | O14: -0.034887985 | P14: -0.037844461 | Q14: -0.038902217 | R14: -0.038488352 | S14: -0.039430752 | T14: -0.027873299 | U14: -0.03966294 | V14: -0.039044093 | W14: -0.027426104 | X14: -0.038296281 | Y14: -0.038869558 | Z14: -0.004196603 | AA14: -0.017576082 | AB14: -0.015633813 | AC14: -0.03950837 | AD14: -0.012201465 | AE14: -0.026888993 | AF14: -0.027254167 | AG14: -0.027621575 | AH14: -0.02556269 | AI14: -0.0073172801
A15: Baseline Absorbance | B15: 0.686 | C15: 1.183 | D15: 0.069 | E15: 1.2 | F15: 0.35 | G15: 0.044 | H15: 0.745 | I15: 0.881 | J15: 0.297 | K15: 0.4 | L15: 0.23 | M15: 0.488 | N15: 0.113 | O15: 0.848 | P15: 0.138 | Q15: 0.121 | R15: 0.521 | S15: 0.855 | T15: 0.029 | U15: 0.252 | V15: 0.204 | W15: 0.042 | X15: 0.09 | Y15: 0.021 | Z15: 0.474 | AA15: 0.372 | AB15: 0.414 | AC15: 0.575 | AD15: 0.31 | AE15: 0.072 | AF15: 0.053 | AG15: 0.033 | AH15: 0.38 | AI15: 0.562
A16: Peak Absorbance | B16: 15.767384 | C16: 11.91475 | D16: 1.0089347 | E16: 11.015688 | F16: 0.97694186 | G16: 3.898632 | H16: 19.843533 | I16: 31.956876 | J16: 13.208412 | K16: 3.9582468 | L16: 0.80508757 | M16: 26.039974 | N16: 5.314811 | O16: 22.821069 | P16: 3.8887247 | Q16: 4.1763226 | R16: 33.250754 | S16: 42.477632 | T16: 1.0633651 | U16: 25.659473 | V16: 26.84614 | W16: 1.0973033 | X16: 19.439409 | Y16: 0.77627338 | Z16: 1.2792277 | AA16: 1.1178483 | AB16: 1.2020854 | AC16: 46.837628 | AD16: 1.1087119 | AE16: 1.0376826 | AF16: 1.1755258 | AG16: 1.0786253 | AH16: 54.210432 | AI16: 2.7828593
A17: Filename | B17: 2019Oct30-5 | C17: 2019Oct30-16 | D17: 2019Oct30-23 | E17: 2019Oct30-24 | F17: 2019Oct30-29 | G17: 2019Oct30-30 | H17: 2019Oct30-45 | I17: 2019Oct30-50 | J17: 2019Oct30-59 | K17: 2019Oct30-62 | L17: 2019Oct31-76 | M17: 2019Oct31-79 | N17: 2019Oct31-90 | O17: 2019Oct31-93 | P17: 2019Oct31-98 | Q17: 2019Oct31-99 | R17: 2019Oct31-106 | S17: 2019Oct31-119 | T17: 2019Oct31-125 | U17: 2019Oct31-147 | V17: 2019Oct31-148 | W17: 2019Oct31-149 | X17: 2019Oct31-150 | Y17: 2019Oct31-156 | Z17: 2019Oct31-169 | AA17: 2019Oct31-170 | AB17: 2019Oct31-171 | AC17: 2019Oct31-173 | AD17: 2019Oct31-179 | AE17: 2019Oct31-183 | AF17: 2019Oct31-186 | AG17: 2019Oct31-199 | AH17: 2019Oct31-200 | AI17: 2019Oct31-201
A18: 350 | B18: 1.5189588 | C18: 2.4425652 | D18: 1.5543633 | E18: 1.7831658 | F18: 1.5551681 | G18: 1.2644527 | H18: 0.94719317 | I18: 1.3482484 | J18: 1.216908 | K18: 1.6539044 | L18: 0.6520746 | M18: 1.0814037 | N18: 1.3714454 | O18: 1.1423529 | P18: 1.2043006 | Q18: 1.1828899 | R18: 0.96245759 | S18: 0.91654463 | T18: 0.88943447 | U18: 0.97117098 | V18: 1.0468754 | W18: 0.95138527 | X18: 0.93744467 | Y18: 1.2525266 | Z18: 1.7075916 | AA18: 1.3179624 | AB18: 1.4135524 | AC18: 1.1485296 | AD18: 0.47201001 | AE18: 1.3151319 | AF18: 0.98795056 | AG18: 0.91811088 | AH18: 0.93540025 | AI18: 0.62903581
A19: 351 | B19: 1.5259873 | C19: 2.2967362 | D19: 1.5671302 | E19: 1.8285014 | F19: 1.118126 | G19: 1.3251589 | H19: 0.94148592 | I19: 1.357323 | J19: 1.2224844 | K19: 1.6640217 | L19: 0.97028701 | M19: 1.099915 | N19: 1.3556817 | O19: 1.1820379 | P19: 1.2554907 | Q19: 1.1703138 | R19: 0.94620327 | S19: 0.8681575 | T19: 0.82949432 | U19: 0.96707769 | V19: 0.96114653 | W19: 1.0300356 | X19: 0.92550632 | Y19: 1.2948954 | Z19: 1.3002534 | AA19: 1.0176332 | AB19: 1.3234607 | AC19: 1.0674275 | AD19: 0.53961888 | AE19: 1.3410203 | AF19: 0.99329564 | AG19: 0.96688552 | AH19: 0.93675636 | AI19: 1.1126324
A20: 352 | B20: 1.5420336 | C20: 2.2966431 | D20: 1.5437243 | E20: 1.9022609 | F20: 0.6778938 | G20: 1.2771647 | H20: 0.95148669 | I20: 1.322698 | J20: 1.2221746 | K20: 1.7030859 | L20: 1.086791 | M20: 1.1091902 | N20: 1.3466464 | O20: 1.2053846 | P20: 1.3346754 | Q20: 1.1885614 | R20: 0.9224634 | S20: 0.88656094 | T20: 0.83626176 | U20: 0.97498875 | V20: 0.9369743 | W20: 1.0196121 | X20: 0.9423027 | Y20: 1.2962194 | Z20: 1.33751 | AA20: 1.0591966 | AB20: 1.1648484 | AC20: 1.1185919 | AD20: 0.42318139 | AE20: 1.3482691 | AF20: 0.99418649 | AG20: 1.0060965 | AH20: 0.88957116 | AI20: 0.94828161
A21: 353 | B21: 1.4803018 | C21: 2.4172199 | D21: 1.5735136 | E21: 1.8619173 | F21: 0.60292673 | G21: 1.2309865 | H21: 0.96866079 | I21: 1.2972764 | J21: 1.2102472 | K21: 1.6215851 | L21: 0.61729729 | M21: 1.0821864 | N21: 1.3137732 | O21: 1.1745287 | P21: 1.3194783 | Q21: 1.2090283 | R21: 0.95332217 | S21: 0.91214799 | T21: 0.84109564 | U21: 0.99132253 | V21: 0.95536621 | W21: 1.0196121 | X21: 0.97610218 | Y21: 1.2670909 | Z21: 1.6827539 | AA21: 1.226791 | AB21: 0.9186822 | AC21: 1.1095997 | AD21: 0.41191325 | AE21: 1.3658732 | AF21: 1.0182394 | AG21: 0.98601283 | AH21: 0.91097169 | AI21: 1.0347346
A22: 354 | B22: 1.5536373 | C22: 2.2490273 | D22: 1.5118072 | E22: 1.8582497 | F22: 1.2010683 | G22: 1.2421419 | H22: 0.96599042 | I22: 1.2956674 | J22: 1.1949894 | K22: 1.5327773 | L22: 0.85030528 | M22: 1.0928314 | N22: 1.2793621 | O22: 1.2184006 | P22: 1.2914837 | Q22: 1.1851092 | R22: 0.98360043 | S22: 0.90902469 | T22: 0.87106572 | U22: 1.0062394 | V22: 0.95469059 | W22: 1.0357212 | X22: 0.95362088 | Y22: 1.2419344 | Z22: 1.7547833 | AA22: 1.4708085 | AB22: 1.4744595 | AC22: 1.0870113 | AD22: 0.46825397 | AE22: 1.3865839 | AF22: 1.0280387 | AG22: 0.98505647 | AH22: 0.9321493 | AI22: 1.0959722
A23: 355 | B23: 1.5240644 | C23: 2.2977612 | D23: 1.5022321 | E23: 1.8895262 | F23: 1.7130775 | G23: 1.2203499 | H23: 0.96101622 | I23: 1.3129477 | J23: 1.1539404 | K23: 1.5333394 | L23: 0.79466158 | M23: 1.0633229 | N23: 1.3222318 | O23: 1.2505308 | P23: 1.2690881 | Q23: 1.1823967 | R23: 0.98457813 | S23: 0.9237042 | T23: 0.8797667 | U23: 0.98872487 | V23: 0.96137173 | W23: 1.0461448 | X23: 0.94333632 | Y23: 1.1505768 | Z23: 1.3635895 | AA23: 1.2603099 | AB23: 1.2054532 | AC23: 1.0878975 | AD23: 0.25541125 | AE23: 1.3348071 | AF23: 1.0164577 | AG23: 0.96688552 | AH23: 0.93978439 | AI23: 1.1423506
A24: 356 | B24: 1.5147814 | C24: 2.2179979 | D24: 1.4852096 | E24: 1.8110803 | F24: 1.260085 | G24: 1.2084163 | H24: 0.98033707 | I24: 1.283021 | J24: 1.155412 | K24: 1.5428947 | L24: 0.97376474 | M24: 1.0661407 | N24: 1.3416481 | O24: 1.2153059 | P24: 1.204034 | Q24: 1.1966989 | R24: 0.99380521 | S24: 0.93845579 | T24: 0.8633315 | U24: 0.98526132 | V24: 0.97251949 | W24: 1.0745726 | X24: 0.95207044 | Y24: 1.1466047 | Z24: 0.97736336 | AA24: 0.93316563 | AB24: 0.76387663 | AC24: 1.0799862 | AD24: 0.62725999 | AE24: 1.3389492 | AF24: 0.9906231 | AG24: 0.95540914 | AH24: 0.93911562 | AI24: 0.74835899
A25: 357 | B25: 1.5623898 | C25: 2.2059775 | D25: 1.4979764 | E25: 1.808839 | F25: 1.5934492 | G25: 1.1866243 | H25: 0.94159064 | I25: 1.2791916 | J25: 1.1933629 | K25: 1.5878606 | L25: 0.98419793 | M25: 1.1011282 | N25: 1.3043534 | O25: 1.1816283 | P25: 1.2485587 | Q25: 1.2183987 | R25: 1.0286054 | S25: 0.91051426 | T25: 0.88363381 | U25: 0.99490415 | V25: 0.97131838 | W25: 1.043302 | X25: 0.96871178 | Y25: 1.1558729 | Z25: 0.98729843 | AA25: 0.89294297 | AB25: 0.79306129 | AC25: 1.04726 | AD25: 0.42318139 | AE25: 1.3027054 | AF25: 0.99596819 | AG25: 0.96306006 | AH25: 0.94897993 | AI25: 0.73349988
A26: 358 | B26: 1.5158423 | C26: 2.2664523 | D26: 1.5160628 | E26: 1.8697619 | F26: 1.6684163 | G26: 1.1982986 | H26: 0.95373817 | I26: 1.2677358 | J26: 1.1911943 | K26: 1.5448619 | L26: 0.6572912 | M26: 1.0783511 | N26: 1.3210784 | O26: 1.2427941 | P26: 1.2394938 | Q26: 1.2359066 | R26: 1.0170868 | S26: 0.89547436 | T26: 0.91553744 | U26: 0.97022637 | V26: 0.95634211 | W26: 1.0053982 | X26: 0.95610157 | Y26: 1.163817 | Z26: 0.96991205 | AA26: 0.82724597 | AB26: 0.81843925 | AC26: 1.0535502 | AD26: 0.61473983 | AE26: 1.3493046 | AF26: 0.97280614 | AG26: 0.97931827 | AH26: 0.89581298 | AI26: 0.73800264
A27: 359 | B27: 1.4901152 | C27: 2.236541 | D27: 1.5054238 | E27: 1.812201 | F27: 1.7194577 | G27: 1.1809169 | H27: 0.95190557 | I27: 1.3268492 | J27: 1.1595169 | K27: 1.5159151 | L27: 0.50079329 | M27: 1.0635969 | N27: 1.2826302 | O27: 1.1814462 | P27: 1.2645556 | Q27: 1.1868353 | R27: 1.0319662 | S27: 0.91073049 | T27: 0.90877 | U27: 0.98278174 | V27: 0.96917892 | W27: 1.0290881 | X27: 0.9757921 | Y27: 1.1757332 | Z27: 1.110245 | AA27: 1.0605374 | AB27: 0.83747272 | AC27: 1.0820181 | AD27: 0.706137 | AE27: 1.3575889 | AF27: 0.97726038 | AG27: 0.97358008 | AH27: 0.89419679 | AI27: 0.79608827
A28: 360 | B28: 1.4529834 | C28: 2.2898408 | D28: 1.4958486 | E28: 1.797225 | F28: 1.8327058 | G28: 1.1827329 | H28: 0.98703916 | I28: 1.327171 | J28: 1.1568835 | K28: 1.5145099 | L28: 0.4347164 | M28: 1.044616 | N28: 1.2680199 | O28: 1.1893195 | P28: 1.2930834 | Q28: 1.1745058 | R28: 1.0308968 | S28: 0.92541 | T28: 0.94550751 | U28: 0.95885177 | V28: 0.9814527 | W28: 0.99876502 | X28: 0.95470618 | Y28: 1.1545488 | Z28: 0.91899477 | AA28: 1.0417668 | AB28: 0.82732153 | AC28: 1.0802456 | AD28: 0.47451405 | AE28: 1.2964922 | AF28: 0.96924275 | AG28: 0.97644918 | AH28: 0.90738636 | AI28: 0.73349988
A29: 361 | B29: 1.4676372 | C29: 2.2698068 | D29: 1.469251 | E29: 1.7658466 | F29: 1.6923419 | G29: 1.1617192 | H29: 1.0025377 | I29: 1.3312577 | J29: 1.1631571 | K29: 1.4816286 | L29: 0.55643699 | M29: 1.0473555 | N29: 1.2862828 | O29: 1.1887279 | P29: 1.292017 | Q29: 1.1925068 | R29: 1.008593 | S29: 0.93533249 | T29: 0.93293942 | U29: 0.9464932 | V29: 0.99496513 | W29: 0.98834147 | X29: 0.98261401 | Y29: 1.1452807 | Z29: 0.80474137 | AA29: 0.86612787 | AB29: 0.93517787 | AC29: 1.0780192 | AD29: 0.61849588 | AE29: 1.3223806 | AF29: 1.0022041 | AG29: 0.99175103 | AH29: 0.90961558 | AI29: 0.86993356
... A418: 750 | B418: -0.045486542 | C418: -0.057213407 | D418: -0.059578609 | E418: -0.094746285 | F418: 0.17704991 | G418: 0.016084544 | H418: 0.0069115256 | I418: -0.00057922744 | J418: -0.0063509708 | K418: -0.10257861 | L418: -0.10085421 | M418: 0.00023481551 | N418: -0.0049982593 | O418: -0.025394723 | P418: -0.0090649148 | Q418: -0.0073976852 | R418: -0.0036052822 | S418: 0.0014174981 | T418: -0.028036521 | U418: 0.010981021 | V418: 0.019968366 | W418: 0.0018951898 | X418: 0.027701105 | Y418: -0.018536334 | Z418: -0.58865341 | AA418: -0.33652956 | AB418: -0.34767807 | AC418: -0.00047554583 | AD418: -0.3217681 | AE418: -0.065238825 | AF418: -0.022271203 | AG418: -0.020083676 | AH418: 0.003399564 | AI418: -0.11662153

Sheet HAGO101OD
A1: Species | B1: Hawaiian Goose | C1: Hawaiian Goose | D1: Hawaiian Goose | E1: Hawaiian Goose | F1: Hawaiian Goose | G1: Hawaiian Goose | H1: Hawaiian Goose | I1: Hawaiian Goose | J1: Hawaiian Goose | K1: Hawaiian Goose | L1: Hawaiian Goose | M1: Hawaiian Goose | N1: Hawaiian Goose | O1: Hawaiian Goose | P1: Hawaiian Goose | Q1: Hawaiian Goose | R1: Hawaiian Goose | S1: Hawaiian Goose | T1: Hawaiian Goose | U1: Hawaiian Goose | V1: Hawaiian Goose | W1: Hawaiian Goose | X1: Hawaiian Goose | Y1: Hawaiian Goose | Z1: Hawaiian Goose | AA1: Hawaiian Goose | AB1: Hawaiian Goose | AC1: Hawaiian Goose | AD1: Hawaiian Goose | AE1: Hawaiian Goose | AF1: Hawaiian Goose | AG1: Hawaiian Goose | AH1: Hawaiian Goose | AI1: Hawaiian Goose | AJ1: Hawaiian Goose | AK1: Hawaiian Goose | AL1: Hawaiian Goose | AM1: Hawaiian Goose | AN1: Hawaiian Goose | AO1: Hawaiian Goose | AP1: Hawaiian Goose | AQ1: Hawaiian Goose | AR1: Hawaiian Goose | AS1: Hawaiian Goose | AT1: Hawaiian Goose | AU1: Hawaiian Goose | AV1: Hawaiian Goose | AW1: Hawaiian Goose | AX1: Hawaiian Goose | AY1: Hawaiian Goose | AZ1: Hawaiian Goose | BA1: Hawaiian Goose | BB1: Hawaiian Goose | BC1: Hawaiian Goose | BD1: Hawaiian Goose | BE1: Hawaiian Goose | BF1: Hawaiian Goose | BG1: Hawaiian Goose | BH1: Hawaiian Goose | BI1: Hawaiian Goose | BJ1: Hawaiian Goose | BK1: Hawaiian Goose | BL1: Hawaiian Goose | BM1: Hawaiian Goose | BN1: Hawaiian Goose | BO1: Hawaiian Goose | BP1: Hawaiian Goose | BQ1: Hawaiian Goose | BR1: Hawaiian Goose | BS1: Hawaiian Goose | BT1: Hawaiian Goose | BU1: Hawaiian Goose | BV1: Hawaiian Goose | BW1: Hawaiian Goose | BX1: Hawaiian Goose | BY1: Hawaiian Goose | BZ1: Hawaiian Goose | CA1: Hawaiian Goose | CB1: Hawaiian Goose
A2: Bird ID | B2: LE OD Only | C2: LE OD Only | D2: LE OD Only | E2: LE OD Only | F2: LE OD Only | G2: LE OD Only | H2: LE OD Only | I2: LE OD Only | J2: LE OD Only | K2: LE OD Only | L2: LE OD Only | M2: LE OD Only | N2: LE OD Only | O2: LE OD Only | P2: LE OD Only | Q2: LE OD Only | R2: LE OD Only | S2: LE OD Only | T2: LE OD Only | U2: LE OD Only | V2: LE OD Only | W2: LE OD Only | X2: LE OD Only | Y2: LE OD Only | Z2: LE OD Only | AA2: LE OD Only | AB2: LE OD Only | AC2: LE OD Only | AD2: LE OD Only | AE2: LE OD Only | AF2: LE OD Only | AG2: LE OD Only | AH2: LE OD Only | AI2: LE OD Only | AJ2: LE OD Only | AK2: LE OD Only | AL2: LE OD Only | AM2: LE OD Only | AN2: LE OD Only | AO2: LE OD Only | AP2: LE OD Only | AQ2: LE OD Only | AR2: LE OD Only | AS2: LE OD Only | AT2: LE OD Only | AU2: LE OD Only | AV2: LE OD Only | AW2: LE OD Only | AX2: LE OD Only | AY2: LE OD Only | AZ2: LE OD Only | BA2: LE OD Only | BB2: LE OD Only | BC2: LE OD Only | BD2: LE OD Only | BE2: LE OD Only | BF2: LE OD Only | BG2: LE OD Only | BH2: LE OD Only | BI2: LE OD Only | BJ2: LE OD Only | BK2: LE OD Only | BL2: LE OD Only | BM2: LE OD Only | BN2: LE OD Only | BO2: LE OD Only | BP2: LE OD Only | BQ2: LE OD Only | BR2: LE OD Only | BS2: LE OD Only | BT2: LE OD Only | BU2: LE OD Only | BV2: LE OD Only | BW2: LE OD Only | BX2: LE OD Only | BY2: LE OD Only | BZ2: LE OD Only | CA2: LE OD Only | CB2: LE OD Only
A3: Prep # | B3: 1 | C3: 1 | D3: 1 | E3: 1 | F3: 1 | G3: 1 | H3: 1 | I3: 1 | J3: 1 | K3: 1 | L3: 1 | M3: 1 | N3: 1 | O3: 1 | P3: 1 | Q3: 1 | R3: 1 | S3: 1 | T3: 1 | U3: 1 | V3: 1 | W3: 1 | X3: 1 | Y3: 1 | Z3: 1 | AA3: 1 | AB3: 1 | AC3: 2 | AD3: 2 | AE3: 2 | AF3: 2 | AG3: 2 | AH3: 2 | AI3: 2 | AJ3: 2 | AK3: 2 | AL3: 2 | AM3: 2 | AN3: 2 | AO3: 2 | AP3: 2 | AQ3: 2 | AR3: 2 | AS3: 2 | AT3: 2 | AU3: 2 | AV3: 2 | AW3: 2 | AX3: 2 | AY3: 2 | AZ3: 2 | BA3: 2 | BB3: 2 | BC3: 3 | BD3: 3 | BE3: 3 | BF3: 3 | BG3: 3 | BH3: 3 | BI3: 3 | BJ3: 3 | BK3: 3 | BL3: 3 | BM3: 3 | BN3: 3 | BO3: 3 | BP3: 3 | BQ3: 3 | BR3: 3 | BS3: 3 | BT3: 3 | BU3: 3 | BV3: 3 | BW3: 3 | BX3: 3 | BY3: 3 | BZ3: 3 | CA3: 3 | CB3: 3
A4: Age | B4: AD | C4: AD | D4: AD | E4: AD | F4: AD | G4: AD | H4: AD | I4: AD | J4: AD | K4: AD | L4: AD | M4: AD | N4: AD | O4: AD | P4: AD | Q4: AD | R4: AD | S4: AD | T4: AD | U4: AD | V4: AD | W4: AD | X4: AD | Y4: AD | Z4: AD | AA4: AD | AB4: AD | AC4: AD | AD4: AD | AE4: AD | AF4: AD | AG4: AD | AH4: AD | AI4: AD | AJ4: AD | AK4: AD | AL4: AD | AM4: AD | AN4: AD | AO4: AD | AP4: AD | AQ4: AD | AR4: AD | AS4: AD | AT4: AD | AU4: AD | AV4: AD | AW4: AD | AX4: AD | AY4: AD | AZ4: AD | BA4: AD | BB4: AD | BC4: AD | BD4: AD | BE4: AD | BF4: AD | BG4: AD | BH4: AD | BI4: AD | BJ4: AD | BK4: AD | BL4: AD | BM4: AD | BN4: AD | BO4: AD | BP4: AD | BQ4: AD | BR4: AD | BS4: AD | BT4: AD | BU4: AD | BV4: AD | BW4: AD | BX4: AD | BY4: AD | BZ4: AD | CA4: AD | CB4: AD
A5: Cellular Component | B5: O | C5: O | D5: O | E5: O | F5: O | G5: O | H5: O | I5: O | J5: O | K5: O | L5: O | M5: O | N5: O | O5: O | P5: O | Q5: O | R5: O | S5: O | T5: O | U5: O | V5: O | W5: O | X5: O | Y5: O | Z5: O | AA5: O | AB5: O | AC5: O | AD5: O | AE5: O | AF5: O | AG5: O | AH5: O | AI5: O | AJ5: O | AK5: O | AL5: O | AM5: O | AN5: O | AO5: O | AP5: O | AQ5: O | AR5: O | AS5: O | AT5: O | AU5: O | AV5: O | AW5: O | AX5: O | AY5: O | AZ5: O | BA5: O | BB5: O | BC5: O | BD5: O | BE5: O | BF5: O | BG5: O | BH5: O | BI5: O | BJ5: O | BK5: O | BL5: O | BM5: O | BN5: O | BO5: O | BP5: O | BQ5: O | BR5: O | BS5: O | BT5: O | BU5: O | BV5: O | BW5: O | BX5: O | BY5: O | BZ5: O | CA5: O | CB5: O
A6: Type | B6: Y | C6: Y | D6: I | E6: I | F6: I | G6: Y | H6: B | I6: B | J6: B | K6: R | L6: I | M6: R | N6: I | O6: I | P6: I | Q6: Y | R6: I | S6: I | T6: I | U6: I | V6: I | W6: R | X6: R | Y6: B | Z6: I | AA6: R | AB6: R | AC6: I | AD6: Y | AE6: I | AF6: I | AG6: B | AH6: B | AI6: Y | AJ6: Y | AK6: Y | AL6: I | AM6: I | AN6: B | AO6: I | AP6: I | AQ6: I | AR6: R | AS6: R | AT6: B | AU6: I | AV6: I | AW6: I | AX6: Y | AY6: I | AZ6: R | BA6: R | BB6: I | BC6: B | BD6: R | BE6: B | BF6: R | BG6: B | BH6: B | BI6: B | BJ6: Y | BK6: Y | BL6: I | BM6: Y | BN6: R | BO6: B | BP6: B | BQ6: B | BR6: B | BS6: B | BT6: B | BU6: Y | BV6: Y | BW6: B | BX6: Y | BY6: I | BZ6: B | CA6: I | CB6: Y
A7: Lambda Mid | B7: 538.4 | C7: 536.6 | D7: 524 | E7: 514.4 | F7: 527.5 | G7: 533.7 | H7: 458.9 | I7: 464.5 | J7: 453.3 | K7: 590.7 | L7: 461.9 | M7: 579.1 | N7: 466.8 | O7: 520.7 | P7: 462.1 | Q7: 533 | R7: 520.9 | S7: 521.9 | T7: 468.8 | U7: 527 | V7: 541 | W7: 592 | X7: 591.4 | Y7: 454.3 | Z7: 465.3 | AA7: 593.3 | AB7: 589.8 | AC7: 524.6 | AD7: 538.7 | AE7: 529.8 | AF7: 527.1 | AG7: 457.4 | AH7: 454.8 | AI7: 528.9 | AJ7: 530.7 | AK7: 530.1 | AL7: 495.3 | AM7: 517.3 | AN7: 465.1 | AO7: 512.8 | AP7: 521.1 | AQ7: 519.8 | AR7: 582.2 | AS7: 586.4 | AT7: 475.2 | AU7: 517.4 | AV7: 499 | AW7: 520.1 | AX7: 538.4 | AY7: 502.1 | AZ7: 592.1 | BA7: 590.3 | BB7: 518.8 | BC7: 458.9 | BD7: 586.8 | BE7: 458.9 | BF7: 588.4 | BG7: 459.2 | BH7: 470.3 | BI7: 458.6 | BJ7: 525.4 | BK7: 532.1 | BL7: 519.2 | BM7: 536.4 | BN7: 590.8 | BO7: 457.8 | BP7: 458.2 | BQ7: 460.1 | BR7: 447.1 | BS7: 439.2 | BT7: 457.7 | BU7: 521.5 | BV7: 536.7 | BW7: 462.9 | BX7: 534.6 | BY7: 518.9 | BZ7: 463 | CA7: 519.5 | CB7: 539.9
A8: Lambda Cut | B8: 521.1793 | C8: 521.55109 | D8: 510.79849 | E8: 497.64651 | F8: 505.93616 | G8: 519.89911 | H8: 402.09025 | I8: 428.14723 | J8: 404.5606 | K8: 573.55384 | L8: 438.9016 | M8: 561.13781 | N8: 439.76089 | O8: 506.6553 | P8: 438.10238 | Q8: 518.74152 | R8: 507.9132 | S8: 509.08709 | T8: 437.32967 | U8: 504.73669 | V8: 525.3938 | W8: 573.96585 | X8: 573.27431 | Y8: 406.6298 | Z8: 439.68613 | AA8: 576.72458 | AB8: 571.75061 | AC8: 511.76367 | AD8: 524.66171 | AE8: 515.36264 | AF8: 513.78405 | AG8: 431.56747 | AH8: 426.03356 | AI8: 514.63483 | AJ8: 515.31028 | AK8: 515.15879 | AL8: 469.41495 | AM8: 498.89145 | AN8: 442.31267 | AO8: 495.8226 | AP8: 507.73367 | AQ8: 502.26897 | AR8: 558.9149 | AS8: 561.53239 | AT8: 419.46955 | AU8: 502.41361 | AV8: 434.50541 | AW8: 503.80216 | AX8: 522.35511 | AY8: 489.70743 | AZ8: 574.09556 | BA8: 571.83233 | BB8: 502.88296 | BC8: 430.68673 | BD8: 569.35075 | BE8: 414.11328 | BF8: 570.9887 | BG8: 417.89946 | BH8: 422.60686 | BI8: 406.8664 | BJ8: 512.22627 | BK8: 518.88315 | BL8: 504.06812 | BM8: 520.01636 | BN8: 573.52317 | BO8: 433.45385 | BP8: 423.19382 | BQ8: 426.06438 | BR8: 382.79096 | BS8: 387.74273 | BT8: 419.18939 | BU8: 508.02883 | BV8: 522.47664 | BW8: 421.39499 | BX8: 520.6618 | BY8: 501.63686 | BZ8: 429.65884 | CA8: 504.9229 | CB8: 523.49929
A9: Lambda 0 | B9: 533.92262 | C9: 532.68728 | D9: 520.56761 | E9: 510.04409 | F9: 521.8934 | G9: 530.11177 | H9: 444.12946 | I9: 455.04828 | J9: 440.62776 | K9: 586.242 | L9: 455.92042 | M9: 574.42983 | N9: 459.76983 | O9: 517.04838 | P9: 455.86062 | Q9: 529.2928 | R9: 517.52343 | S9: 518.56864 | T9: 460.61771 | U9: 521.21154 | V9: 536.94239 | W9: 587.31112 | X9: 586.68732 | Y9: 441.90575 | Z9: 458.64039 | AA9: 588.99039 | AB9: 585.10716 | AC9: 521.26255 | AD9: 535.05005 | AE9: 526.04629 | AF9: 523.63785 | AG9: 450.68354 | AH9: 447.32073 | AI9: 525.19106 | AJ9: 526.69867 | AK9: 526.21529 | AL9: 488.56989 | AM9: 512.51378 | AN9: 459.17529 | AO9: 508.38588 | AP9: 517.62475 | AQ9: 515.24193 | AR9: 576.14587 | AS9: 579.93442 | AT9: 460.71008 | AU9: 513.50354 | AV9: 482.23141 | AW9: 515.86256 | AX9: 534.22833 | AY9: 498.87793 | AZ9: 587.41885 | BA9: 585.49841 | BB9: 514.66157 | BC9: 451.56455 | BD9: 582.26319 | BE9: 447.25545 | BF9: 583.87306 | BG9: 448.46186 | BH9: 457.89978 | BI9: 445.14926 | BJ9: 521.97483 | BK9: 528.66362 | BL9: 515.26571 | BM9: 532.14025 | BN9: 586.30802 | BO9: 451.47 | BP9: 449.09839 | BQ9: 451.25074 | BR9: 430.37965 | BS9: 425.82111 | BT9: 447.68724 | BU9: 517.9975 | BV9: 533.00193 | BW9: 452.1087 | BX9: 530.97607 | BY9: 514.41158 | BZ9: 454.3313 | CA9: 515.70995 | CB9: 535.63582
A10: b | B10: 0.083910665 | C10: 0.096020249 | D10: 0.10945714 | E10: 0.086250678 | F10: 0.067010335 | G10: 0.10470342 | H10: 0.025435775 | I10: 0.03974938 | J10: 0.029647473 | K10: 0.084275409 | L10: 0.062830464 | M10: 0.080446754 | N10: 0.053441109 | O10: 0.10288581 | P10: 0.06021431 | Q10: 0.1013432 | R10: 0.11126686 | S10: 0.11277684 | T10: 0.045916266 | U10: 0.064904991 | V10: 0.092591393 | W10: 0.080125768 | X10: 0.079721124 | Y10: 0.030312439 | Z10: 0.056414744 | AA10: 0.087177294 | AB10: 0.080058109 | AC10: 0.11257109 | AD10: 0.10293279 | AE10: 0.10008753 | AF10: 0.10851645 | AG10: 0.055937222 | AH10: 0.050232152 | AI10: 0.1012957 | AJ10: 0.09389386 | AK10: 0.096712393 | AL10: 0.055823732 | AM10: 0.07849614 | AN10: 0.06341242 | AO10: 0.085113172 | AP10: 0.10810745 | AQ10: 0.082425277 | AR10: 0.06205686 | AS10: 0.058107716 | AT10: 0.025928375 | AU10: 0.096420812 | AV10: 0.022404981 | AW10: 0.088662079 | AX10: 0.090059815 | AY10: 0.11660214 | AZ10: 0.08025799 | BA10: 0.078244865 | BB10: 0.090783211 | BC10: 0.051217032 | BD10: 0.082811566 | BE10: 0.032264029 | BF10: 0.082992091 | BG10: 0.034987435 | BH10: 0.030297856 | BI10: 0.027931556 | BJ10: 0.10968796 | BK10: 0.10933017 | BL10: 0.095493774 | BM10: 0.088197761 | BN10: 0.083638023 | BO10: 0.059352293 | BP10: 0.041278432 | BQ10: 0.042455516 | BR10: 0.022469624 | BS10: 0.028081552 | BT10: 0.037522127 | BU10: 0.10726612 | BV10: 0.10159345 | BW10: 0.034815076 | BX10: 0.10367192 | BY10: 0.083704339 | BZ10: 0.043339826 | CA10: 0.099128058 | CB10: 0.088105958
A11: Bmid | B11: 0.029034832 | C11: 0.033225 | D11: 0.037874442 | E11: 0.029844525 | F11: 0.023186967 | G11: 0.036229557 | H11: 0.0088013061 | I11: 0.013754111 | J11: 0.010258641 | K11: 0.029161041 | L11: 0.021740645 | M11: 0.027836247 | N11: 0.018491733 | O11: 0.035600626 | P11: 0.020835401 | Q11: 0.035066851 | R11: 0.038500644 | S11: 0.039023128 | T11: 0.015887981 | U11: 0.022458474 | V11: 0.032038544 | W11: 0.027725179 | X11: 0.027585164 | Y11: 0.010488733 | Z11: 0.019520673 | AA11: 0.030165154 | AB11: 0.027701768 | AC11: 0.038951935 | AD11: 0.035616883 | AE11: 0.034632363 | AF11: 0.037548943 | AG11: 0.01935544 | AH11: 0.017381368 | AI11: 0.035050414 | AJ11: 0.032489225 | AK11: 0.033464496 | AL11: 0.01931617 | AM11: 0.027161294 | AN11: 0.021942014 | AO11: 0.029450925 | AP11: 0.037407423 | AQ11: 0.028520857 | AR11: 0.021472962 | AS11: 0.020106476 | AT11: 0.0089717561 | AU11: 0.033363603 | AV11: 0.0077525886 | AW11: 0.03067892 | AX11: 0.031162566 | AY11: 0.040346762 | AZ11: 0.027770931 | BA11: 0.027074348 | BB11: 0.031412876 | BC11: 0.017722156 | BD11: 0.028654521 | BE11: 0.011164024 | BF11: 0.028716987 | BG11: 0.012106379 | BH11: 0.010483687 | BI11: 0.0096648982 | BJ11: 0.037954313 | BK11: 0.037830509 | BL11: 0.033042828 | BM11: 0.030518256 | BN11: 0.028940492 | BO11: 0.020537126 | BP11: 0.014283194 | BQ11: 0.01469049 | BR11: 0.0077749563 | BS11: 0.0097168001 | BT11: 0.012983435 | BU11: 0.037116303 | BV11: 0.035153442 | BW11: 0.012046739 | BX11: 0.035872636 | BY11: 0.028963439 | BZ11: 0.01499648 | CA11: 0.034300366 | CB11: 0.030486491
A12: R Squared | B12: 0.98907527 | C12: 0.99546219 | D12: 0.99140305 | E12: 0.99614115 | F12: 0.97366997 | G12: 0.99054406 | H12: 0.15760277 | I12: 0.82504485 | J12: 0.81857087 | K12: 0.99551322 | L12: 0.99589363 | M12: 0.99543101 | N12: 0.99721525 | O12: 0.99572837 | P12: 0.99533612 | Q12: 0.98867291 | R12: 0.99643118 | S12: 0.99413389 | T12: 0.99765609 | U12: 0.99407003 | V12: 0.993783 | W12: 0.99071589 | X12: 0.9957748 | Y12: 0.78889871 | Z12: 0.99532815 | AA12: 0.99432922 | AB12: 0.99437034 | AC12: 0.99188064 | AD12: 0.99164571 | AE12: 0.98906193 | AF12: 0.9921125 | AG12: 0.81602302 | AH12: 0.82009656 | AI12: 0.99338197 | AJ12: 0.98978517 | AK12: 0.98849181 | AL12: 0.95834457 | AM12: 0.99690501 | AN12: 0.79587172 | AO12: 0.99415186 | AP12: 0.99544052 | AQ12: 0.9435101 | AR12: 0.9959262 | AS12: 0.96398499 | AT12: 0.65838954 | AU12: 0.88367143 | AV12: 0.59225032 | AW12: 0.99497642 | AX12: 0.99237759 | AY12: 0.99199343 | AZ12: 0.9929951 | BA12: 0.99320105 | BB12: 0.99496415 | BC12: 0.43325472 | BD12: 0.99502883 | BE12: 0.36490216 | BF12: 0.9927864 | BG12: 0.27515732 | BH12: 0.94606025 | BI12: 0.83892379 | BJ12: 0.99232868 | BK12: 0.99183611 | BL12: 0.99647275 | BM12: 0.99268305 | BN12: 0.99343174 | BO12: 0.54847254 | BP12: 0.8639631 | BQ12: 0.85518409 | BR12: 0.54780955 | BS12: 0.37547099 | BT12: 0.8272274 | BU12: 0.99494433 | BV12: 0.99142353 | BW12: 0.71869951 | BX12: 0.98607294 | BY12: 0.98918467 | BZ12: 0.62625187 | CA12: 0.99398062 | CB12: 0.99343888
A13: Intercept | B13: 16.135536 | C13: 18.368643 | D13: 20.357305 | E13: 15.863822 | F13: 12.734413 | G13: 19.821179 | H13: 4.5367531 | I13: 6.8951992 | J13: 5.1513109 | K13: 17.719422 | L13: 10.524179 | M13: 16.603436 | N13: 9.1196213 | O13: 18.981104 | P13: 10.139811 | Q13: 19.156664 | R13: 20.531074 | S13: 20.926639 | T13: 7.9417342 | U13: 12.317156 | V13: 17.809219 | W13: 16.882763 | X13: 16.854406 | Y13: 5.2677407 | Z13: 9.5911003 | AA13: 18.438662 | AB13: 16.880828 | AC13: 20.965783 | AD13: 19.627945 | AE13: 18.825749 | AF13: 20.254135 | AG13: 9.3521328 | AH13: 8.4081561 | AI13: 19.085023 | AJ13: 17.763449 | AK13: 18.280664 | AL13: 10.083478 | AM13: 14.567225 | AN13: 10.715078 | AO13: 15.596073 | AP13: 20.01534 | AQ13: 15.334149 | AR13: 13.022314 | AS13: 12.280128 | AT13: 4.7664674 | AU13: 17.722204 | AV13: 4.3694739 | AW13: 16.414246 | AX13: 17.314285 | AY13: 20.681974 | AZ13: 16.92533 | BA13: 16.51161 | BB13: 16.842366 | BC13: 8.6239065 | BD13: 17.346497 | BE13: 5.6229505 | BF13: 17.402598 | BG13: 6.0585137 | BH13: 5.4332945 | BI13: 4.930273 | BJ13: 20.404754 | BK13: 20.588062 | BL13: 17.676586 | BM13: 16.841722 | BN13: 17.557381 | BO13: 9.9127508 | BP13: 7.0484375 | BQ13: 7.2589573 | BR13: 3.9769846 | BS13: 4.7659796 | BT13: 6.4378215 | BU13: 19.887037 | BV13: 19.325591 | BW13: 6.082103 | BX13: 19.637431 | BY13: 15.515064 | BZ13: 7.4457794 | CA13: 18.35679 | CB13: 16.997242
A14: Slope | B14: -0.029040939 | C14: -0.033301902 | D14: -0.037896167 | E14: -0.029868232 | F14: -0.023193465 | G14: -0.036201599 | H14: -0.0087959185 | I14: -0.013769093 | J14: -0.010261283 | K14: -0.029150572 | L14: -0.021700033 | M14: -0.02780678 | N14: -0.018463718 | O14: -0.035489818 | P14: -0.020862273 | Q14: -0.03500137 | R14: -0.038453567 | S14: -0.039141906 | T14: -0.015873001 | U14: -0.022421901 | V14: -0.031993562 | W14: -0.027671964 | X14: -0.02765588 | Y14: -0.010495396 | Z14: -0.019539166 | AA14: -0.030237418 | AB14: -0.027775795 | AC14: -0.039013678 | AD14: -0.035504677 | AE14: -0.034588749 | AF14: -0.037475152 | AG14: -0.019353018 | AH14: -0.017388668 | AI14: -0.035141466 | AJ14: -0.032530788 | AK14: -0.033544345 | AL14: -0.019350636 | AM14: -0.027194743 | AN14: -0.021964277 | AO14: -0.029438095 | AP14: -0.037451406 | AQ14: -0.028538791 | AR14: -0.021510098 | AS14: -0.020088116 | AT14: -0.00897912 | AU14: -0.033283741 | AV14: -0.007754734 | AW14: -0.030595831 | AX14: -0.031232173 | AY14: -0.040191291 | AZ14: -0.027739859 | BA14: -0.02712615 | BB14: -0.031503087 | BC14: -0.017701745 | BD14: -0.028710767 | BE14: -0.011163492 | BF14: -0.02872666 | BG14: -0.012104619 | BH14: -0.010490352 | BI14: -0.0096598614 | BJ14: -0.037883169 | BK14: -0.037750429 | BL14: -0.033083993 | BM14: -0.030463892 | BN14: -0.028869594 | BO14: -0.020562168 | BP14: -0.014292358 | BQ14: -0.014690168 | BR14: -0.0077770506 | BS14: -0.009712573 | BT14: -0.012972231 | BU14: -0.037177097 | BV14: -0.03507447 | BW14: -0.012060188 | BX14: -0.035795656 | BY14: -0.028935403 | BZ14: -0.015002087 | CA14: -0.03437513 | CB14: -0.030558288
A15: Baseline Absorbance | B15: 0.092 | C15: 0.036 | D15: 0.565 | E15: 0.787 | F15: 0.552 | G15: 0.091 | H15: 0.4 | I15: 0.38 | J15: 0.268 | K15: 0.035 | L15: 0.743 | M15: 0.019 | N15: 0.538 | O15: 0.379 | P15: 0.557 | Q15: 0.073 | R15: 0.523 | S15: 0.664 | T15: 0.519 | U15: 1.193 | V15: 1.32 | W15: 0.029 | X15: 0.067 | Y15: 0.337 | Z15: 0.589 | AA15: 0.115 | AB15: 0.028 | AC15: 0.46 | AD15: 0.332 | AE15: 0.734 | AF15: 0.781 | AG15: 0.275 | AH15: 0.182 | AI15: 0.248 | AJ15: 0.178 | AK15: 0.176 | AL15: 0.879 | AM15: 0.506 | AN15: 0.29 | AO15: 0.569 | AP15: 1.118 | AQ15: 0.717 | AR15: 0.095 | AS15: 0.13 | AT15: 0.231 | AU15: 0.5 | AV15: 0.585 | AW15: 0.91 | AX15: 0.087 | AY15: 0.954 | AZ15: 0.039 | BA15: 0.028 | BB15: 0.832 | BC15: 0.496 | BD15: 0.04 | BE15: 0.494 | BF15: 0.032 | BG15: 0.378 | BH15: 0.166 | BI15: 0.22 | BJ15: 0.159 | BK15: 0.059 | BL15: 0.416 | BM15: 0.059 | BN15: 0.03 | BO15: 0.45 | BP15: 0.377 | BQ15: 0.327 | BR15: 0.315 | BS15: 0.302 | BT15: 0.235 | BU15: 0.166 | BV15: 0.097 | BW15: 0.327 | BX15: 0.061 | BY15: 0.495 | BZ15: 0.431 | CA15: 0.806 | CB15: 0.081
A16: Peak Absorbance | B16: 2.2274091 | C16: 2.9120106 | D16: 59.651845 | E16: 6.8699516 | F16: 2.8290632 | G16: 3.6275088 | H16: 0.97656611 | I16: 1.0611793 | J16: 1.3153109 | K16: 1.018875 | L16: 40.727557 | M16: 1.3562428 | N16: 30.39705 | O16: 20.484602 | P16: 30.129179 | Q16: 3.9922529 | R16: 30.374655 | S16: 46.562925 | T16: 29.678455 | U16: 14.298982 | V16: 13.110684 | W16: 1.0210491 | X16: 1.0172688 | Y16: 1.2219892 | Z16: 36.776656 | AA16: 1.004798 | AB16: 1.0386436 | AC16: 45.531272 | AD16: 1.9496394 | AE16: 25.73879 | AF16: 39.330976 | AG16: 1.05014 | AH16: 1.1423209 | AI16: 4.3185233 | AJ16: 3.8581501 | AK16: 4.3204654 | AL16: 4.058331 | AM16: 5.6806059 | AN16: 0.92509263 | AO16: 12.95943 | AP16: 60.508554 | AQ16: 2.7963298 | AR16: 1.2710106 | AS16: 1.1465602 | AT16: 1.0337281 | AU16: 1.4206164 | AV16: 3.2906786 | AW16: 8.0908018 | AX16: 2.3904023 | AY16: 18.919836 | AZ16: 1.0333028 | BA16: 1.0558097 | BB16: 23.887254 | BC16: 0.93714809 | BD16: 1.0681224 | BE16: 1.0840495 | BF16: 1.0599605 | BG16: 0.88945015 | BH16: 1.1711289 | BI16: 1.1300451 | BJ16: 7.5302617 | BK16: 4.4520008 | BL16: 14.319141 | BM16: 2.699469 | BN16: 1.0390156 | BO16: 1.190548 | BP16: 1.1991631 | BQ16: 1.1497077 | BR16: 1.2907313 | BS16: 1.1457316 | BT16: 1.0888719 | BU16: 12.205461 | BV16: 2.8119655 | BW16: 1.0312599 | BX16: 3.423811 | BY16: 5.3626272 | BZ16: 0.97101144 | CA16: 21.008615 | CB16: 2.1628209
A17: Filename | B17: 2019Oct31-2 | C17: 2019Oct31-3 | D17: 2019Oct31-4 | E17: 2019Oct31-5 | F17: 2019Oct31-6 | G17: 2019Oct31-7 | H17: 2019Oct31-8 | I17: 2019Oct31-9 | J17: 2019Oct31-10 | K17: 2019Oct31-11 | L17: 2019Oct31-12 | M17: 2019Oct31-15 | N17: 2019Oct31-16 | O17: 2019Oct31-17 | P17: 2019Oct31-18 | Q17: 2019Oct31-19 | R17: 2019Oct31-20 | S17: 2019Oct31-21 | T17: 2019Oct31-22 | U17: 2019Oct31-23 | V17: 2019Oct31-24 | W17: 2019Oct31-25 | X17: 2019Oct31-26 | Y17: 2019Oct31-27 | Z17: 2019Oct31-28 | AA17: 2019Oct31-29 | AB17: 2019Oct31-30 | AC17: 2019Oct31-31 | AD17: 2019Oct31-32 | AE17: 2019Oct31-34 | AF17: 2019Oct31-35 | AG17: 2019Oct31-36 | AH17: 2019Oct31-37 | AI17: 2019Oct31-38 | AJ17: 2019Oct31-39 | AK17: 2019Oct31-40 | AL17: 2019Oct31-41 | AM17: 2019Oct31-42 | AN17: 2019Oct31-44 | AO17: 2019Oct31-45 | AP17: 2019Oct31-46 | AQ17: 2019Oct31-47 | AR17: 2019Oct31-48 | AS17: 2019Oct31-49 | AT17: 2019Oct31-50 | AU17: 2019Oct31-51 | AV17: 2019Oct31-53 | AW17: 2019Oct31-54 | AX17: 2019Oct31-55 | AY17: 2019Oct31-56 | AZ17: 2019Oct31-58 | BA17: 2019Oct31-59 | BB17: 2019Oct31-60 | BC17: 2019Oct31-62 | BD17: 2019Oct31-63 | BE17: 2019Oct31-64 | BF17: 2019Oct31-65 | BG17: 2019Oct31-66 | BH17: 2019Oct31-67 | BI17: 2019Oct31-68 | BJ17: 2019Oct31-70 | BK17: 2019Oct31-71 | BL17: 2019Oct31-72 | BM17: 2019Oct31-73 | BN17: 2019Oct31-74 | BO17: 2019Oct31-75 | BP17: 2019Oct31-76 | BQ17: 2019Oct31-77 | BR17: 2019Oct31-78 | BS17: 2019Oct31-79 | BT17: 2019Oct31-80 | BU17: 2019Oct31-81 | BV17: 2019Oct31-82 | BW17: 2019Oct31-83 | BX17: 2019Oct31-84 | BY17: 2019Oct31-86 | BZ17: 2019Oct31-88 | CA17: 2019Oct31-89 | CB17: 2019Oct31-90
A18: 350 | B18: 1.5514591 | C18: 1.2249607 | D18: 1.1635754 | E18: 1.0420928 | F18: 0.50986726 | G18: 0.91106799 | H18: 0.14395574 | I18: 0.54464372 | J18: 0.96628427 | K18: 1.3955025 | L18: 0.85377961 | M18: 0.97962766 | N18: 0.7545786 | O18: 0.92277764 | P18: 0.80839495 | Q18: 1.0185615 | R18: 0.95240951 | S18: 0.92653586 | T18: 0.96966833 | U18: 0.67106758 | V18: 1.653424 | W18: 1.4303727 | X18: 1.5564017 | Y18: 1.641828 | Z18: 0.7740761 | AA18: 1.5846293 | AB18: 1.3911927 | AC18: 0.90210455 | AD18: 1.6109894 | AE18: 0.99852867 | AF18: 0.98817182 | AG18: -0.35477461 | AH18: -0.18951998 | AI18: 0.84731121 | AJ18: 0.96572148 | AK18: 0.78586735 | AL18: -0.2381004 | AM18: 0.16329746 | AN18: -0.22358943 | AO18: 0.84670186 | AP18: 0.86863981 | AQ18: 0.83344162 | AR18: 1.1700574 | AS18: 0.83910426 | AT18: 1.1685152 | AU18: 0.98955437 | AV18: 1.5700312 | AW18: 0.96173104 | AX18: 1.5346863 | AY18: 0.49276862 | AZ18: 0.9825981 | BA18: 0.90580973 | BB18: 0.72703601 | BC18: 0.51683324 | BD18: 0.983346 | BE18: 0.75417403 | BF18: 1.1245569 | BG18: 1.7440605 | BH18: 1.0277289 | BI18: 1.0735732 | BJ18: 0.98042917 | BK18: 0.95879792 | BL18: 1.065083 | BM18: 1.4520148 | BN18: 1.0198059 | BO18: 0.87502766 | BP18: 1.4656459 | BQ18: 0.94079587 | BR18: 1.6766911 | BS18: 1.1875814 | BT18: 1.2823938 | BU18: 0.95735183 | BV18: 1.1318744 | BW18: 0.48845607 | BX18: 1.0268195 | BY18: 0.66623837 | BZ18: 1.4740428 | CA18: 1.0718414 | CB18: 0.9832738
A19: 351 | B19: 1.6231082 | C19: 1.3157114 | D19: 1.1483436 | E19: 0.97238978 | F19: 0.8076192 | G19: 0.97101412 | H19: 0.85332798 | I19: 0.44922096 | J19: 0.93572983 | K19: 1.4209122 | L19: 0.85935677 | M19: 0.98934915 | N19: 0.77527584 | O19: 0.91452124 | P19: 0.85073204 | Q19: 1.0351463 | R19: 0.89954812 | S19: 0.96472847 | T19: 0.9503607 | U19: 0.75217558 | V19: 1.7177121 | W19: 1.5614146 | X19: 1.6363791 | Y19: 1.4418255 | Z19: 0.76147512 | AA19: 1.413804 | AB19: 1.4713397 | AC19: 0.93072589 | AD19: 1.4038975 | AE19: 0.98941041 | AF19: 0.9780032 | AG19: -0.21802512 | AH19: 0.13745405 | AI19: 0.8787568 | AJ19: 1.0265886 | AK19: 0.78080035 | AL19: 0.30635375 | AM19: 0.3370305 | AN19: 1.2124216 | AO19: 0.85654817 | AP19: 0.87822046 | AQ19: 0.68483604 | AR19: 1.1700574 | AS19: 0.88140377 | AT19: 1.073838 | AU19: 1.3349751 | AV19: 1.3556673 | AW19: 0.81049445 | AX19: 1.484326 | AY19: 0.553328 | AZ19: 0.99366113 | BA19: 0.89899913 | BB19: 0.81651669 | BC19: -0.42616074 | BD19: 0.95416659 | BE19: 0.75078448 | BF19: 1.0428417 | BG19: 1.1320751 | BH19: 1.0625503 | BI19: 1.0548928 | BJ19: 0.99901486 | BK19: 0.93740025 | BL19: 1.1426195 | BM19: 1.4694359 | BN19: 1.037645 | BO19: 1.4786347 | BP19: 1.121432 | BQ19: 1.2057746 | BR19: 1.7699545 | BS19: 1.7493714 | BT19: 1.2390617 | BU19: 0.99364914 | BV19: 1.0125359 | BW19: 0.74688341 | BX19: 1.036038 | BY19: 0.78025696 | BZ19: 0.94072081 | CA19: 1.0052164 | CB19: 1.0212214
A20: 352 | B20: 1.5603567 | C20: 1.3497864 | D20: 1.1308439 | E20: 0.74749896 | F20: 0.7101252 | G20: 0.96281394 | H20: 0.67468412 | I20: 0.49326223 | J20: 1.0684507 | K20: 1.4524203 | L20: 0.82166722 | M20: 0.97214958 | N20: 0.76753949 | O20: 0.93058641 | P20: 0.83460201 | Q20: 1.0348911 | R20: 0.90051959 | S20: 0.96337768 | T20: 0.88136078 | U20: 0.69845965 | V20: 1.6576647 | W20: 1.5402463 | X20: 1.6668968 | Y20: 1.3265699 | Z20: 0.75260469 | AA20: 1.3295152 | AB20: 1.3941611 | AC20: 0.9289953 | AD20: 1.3408427 | AE20: 1.0243637 | AF20: 1.0028022 | AG20: 0.29027013 | AH20: 0.43214721 | AI20: 0.89079456 | AJ20: 0.99262256 | AK20: 0.76463421 | AL20: 0.027364247 | AM20: 0.25876367 | AN20: 0.85341882 | AO20: 0.94266302 | AP20: 0.85821728 | AQ20: 0.92096982 | AR20: 1.1530508 | AS20: 0.93747522 | AT20: 1.4375976 | AU20: 2.1474742 | AV20: 1.3763645 | AW20: 0.83319386 | AX20: 1.502994 | AY20: 0.48041183 | AZ20: 1.0037184 | BA20: 0.92916036 | BB20: 0.73683855 | BC20: -0.99739749 | BD20: 0.92012395 | BE20: 0.21862573 | BF20: 0.99031047 | BG20: 0.44579125 | BH20: 1.0197697 | BI20: 1.0856605 | BJ20: 1.0030847 | BK20: 0.91213278 | BL20: 1.1743389 | BM20: 1.4948102 | BN20: 1.0753055 | BO20: 1.6879392 | BP20: 1.3768557 | BQ20: 1.3832373 | BR20: 1.8129991 | BS20: 1.904634 | BT20: 1.4182455 | BU20: 1.0108426 | BV20: 1.0733102 | BW20: 1.0578482 | BX20: 1.0443644 | BY20: 0.89037221 | BZ20: 0.75553955 | CA20: 0.99714812 | CB20: 0.97270613
A21: 353 | B21: 1.5233615 | C21: 1.3271857 | D21: 1.1475143 | E21: 0.85501255 | F21: 0.85109626 | G21: 0.94528253 | H21: 0.33820926 | I21: 0.39783948 | J21: 0.95100705 | K21: 1.4239614 | L21: 0.82694425 | M21: 0.98561011 | N21: 0.72952756 | O21: 0.93178011 | P21: 0.80311972 | Q21: 1.0027421 | R21: 0.87251444 | S21: 0.95013118 | T21: 0.85828079 | U21: 0.68937983 | V21: 1.6026212 | W21: 1.4807734 | X21: 1.5995474 | Y21: 1.0644198 | Z21: 0.74439748 | AA21: 1.2373595 | AB21: 1.4070242 | AC21: 0.91273216 | AD21: 1.5819347 | AE21: 1.0295627 | AF21: 0.93893703 | AG21: 0.43863042 | AH21: 0.55085752 | AI21: 0.88293316 | AJ21: 0.97794924 | AK21: 0.73905793 | AL21: 0.19689677 | AM21: 0.41684334 | AN21: 0.62825481 | AO21: 0.86954207 | AP21: 0.85946327 | AQ21: 0.31933366 | AR21: 1.1709078 | AS21: 0.86763184 | AT21: 1.2108707 | AU21: 1.5359274 | AV21: 0.73438138 | AW21: 0.70646707 | AX21: 1.4587117 | AY21: 0.44612453 | AZ21: 1.0288617 | BA21: 0.94570038 | BB21: 0.72048652 | BC21: 0.21308037 | BD21: 0.91234277 | BE21: 0.27455324 | BF21: 0.98350087 | BG21: 0.2209404 | BH21: 1.0535962 | BI21: 1.1581844 | BJ21: 1.0161083 | BK21: 0.92032763 | BL21: 1.0526398 | BM21: 1.453151 | BN21: 1.0911625 | BO21: 1.2355715 | BP21: 1.1433254 | BQ21: 1.0988107 | BR21: 1.5578059 | BS21: 1.4696616 | BT21: 1.2027565 | BU21: 0.99788521 | BV21: 1.0810451 | BW21: 1.0393891 | BX21: 1.0535829 | BY21: 0.79135066 | BZ21: 1.0833104 | CA21: 1.0224419 | CB21: 0.95685462
A22: 354 | B22: 1.4629515 | C22: 1.2837227 | D22: 1.1340257 | E22: 0.8079959 | F22: 0.84846128 | G22: 0.93199258 | H22: 0.31045876 | I22: 0.44041271 | J22: 0.9204526 | K22: 1.4290433 | L22: 0.82824476 | M22: 0.99682723 | N22: 0.76526212 | O22: 0.94655211 | P22: 0.7937528 | Q22: 0.99279125 | R22: 0.88809147 | S22: 0.9826156 | T22: 0.91153967 | U22: 0.69060065 | V22: 1.5627592 | W22: 1.5039578 | X22: 1.6132278 | Y22: 0.96611351 | Z22: 0.74635947 | AA22: 1.3014189 | AB22: 1.4060348 | AC22: 0.92284947 | AD22: 1.5411345 | AE22: 1.0563976 | AF22: 0.97131059 | AG22: 0.50184481 | AH22: 0.375916 | AI22: 0.9249425 | AJ22: 0.96191729 | AK22: 0.72795879 | AL22: 0.28936905 | AM22: 0.41916236 | AN22: 0.80145789 | AO22: 0.87688644 | AP22: 0.86239303 | AQ22: 0.34241802 | AR22: 1.2032204 | AS22: 0.99256295 | AT22: 1.3117766 | AU22: 1.9584704 | AV22: 0.99679244 | AW22: 0.8677304 | AX22: 1.4448192 | AY22: 0.42647613 | AZ22: 1.0369075 | BA22: 0.93888979 | BB22: 0.68275109 | BC22: -0.54630181 | BD22: 0.91720601 | BE22: 0.4914842 | BF22: 1.0019841 | BG22: -0.18574635 | BH22: 1.0635452 | BI22: 1.0955502 | BJ22: 1.00417 | BK22: 0.9410424 | BL22: 1.0478927 | BM22: 1.3899046 | BN22: 1.0554842 | BO22: 0.84396958 | BP22: 1.0691309 | BQ22: 0.95173536 | BR22: 1.2585432 | BS22: 1.556182 | BT22: 1.0282573 | BU22: 1.0110087 | BV22: 1.1307695 | BW22: 1.2211402 | BX22: 1.0491223 | BY22: 0.85524216 | BZ22: 1.4184885 | CA22: 1.0660501 | CB22: 0.98855764
A23: 355 | B23: 1.4957321 | C23: 1.2503431 | D23: 1.1151721 | E23: 0.79698151 | F23: 1.316169 | G23: 0.90626099 | H23: 0.80996782 | I23: 0.90284605 | J23: 0.95005222 | K23: 1.3965189 | L23: 0.81596502 | M23: 0.98037546 | N23: 0.77966312 | O23: 0.93854439 | P23: 0.7872264 | Q23: 1.0144791 | R23: 0.91824055 | S23: 0.95065407 | T23: 0.9349969 | U23: 0.69792555 | V23: 1.5767533 | W23: 1.4837975 | X23: 1.6269081 | Y23: 1.0147017 | Z23: 0.72461172 | AA23: 1.3092859 | AB23: 1.398119 | AC23: 0.8975562 | AD23: 1.4527341 | AE23: 1.0433201 | AF23: 0.98446235 | AG23: 0.042572953 | AH23: 0.35925491 | AI23: 0.86082298 | AJ23: 0.95322199 | AK23: 0.72265051 | AL23: 0.071084136 | AM23: 0.27712255 | AN23: 0.70225977 | AO23: 0.8883469 | AP23: 0.85129699 | AQ23: 0.55162004 | AR23: 1.1887648 | AS23: 1.0053512 | AT23: 1.3989792 | AU23: 1.7368797 | AV23: 1.0832772 | AW23: 0.85658958 | AX23: 1.4582776 | AY23: 0.47929861 | AZ23: 0.99868978 | BA23: 0.91067444 | BB23: 0.67750283 | BC23: -0.45109568 | BD23: 0.95319394 | BE23: 1.0338116 | BF23: 1.0058753 | BG23: -0.10753736 | BH23: 1.1272186 | BI23: 1.1504925 | BJ23: 0.97011886 | BK23: 0.94422929 | BL23: 1.0922711 | BM23: 1.3736196 | BN23: 1.0653949 | BO23: 0.63466512 | BP23: 1.0557516 | BQ23: 1.0781472 | BR23: 1.4091994 | BS23: 1.3499553 | BT23: 1.1090657 | BU23: 1.0015399 | BV23: 1.1200879 | BW23: 1.2381793 | BX23: 1.0491223 | BY23: 0.98055989 | BZ23: 1.1851601 | CA23: 1.0591203 | CB23: 0.94196381
A24: 356 | B24: 1.4320441 | C24: 1.2127911 | D24: 1.1377998 | E24: 0.72399063 | F24: 1.3521803 | G24: 0.90824035 | H24: 0.69202818 | I24: 0.40224361 | J24: 0.71611976 | K24: 1.3711091 | L24: 0.83142098 | M24: 0.97887985 | N24: 0.80588632 | O24: 0.94829292 | P24: 0.78993165 | Q24: 0.98411612 | R24: 0.91097127 | S24: 0.94215714 | T24: 0.8983707 | U24: 0.71951874 | V24: 1.5876942 | W24: 1.4636372 | X24: 1.6321698 | Y24: 1.4147066 | Z24: 0.7344217 | AA24: 1.3126574 | AB24: 1.4367083 | AC24: 0.88040559 | AD24: 1.4397522 | AE24: 1.0615966 | AF24: 0.99872954 | AG24: 0.11094769 | AH24: 0.50503951 | AI24: 0.84387185 | AJ24: 0.93365757 | AK24: 0.75039836 | AL24: 0.11983653 | AM24: 0.32002437 | AN24: 1.1809301 | AO24: 0.93322024 | AP24: 0.79411618 | AQ24: 0.6045217 | AR24: 1.1751594 | AS24: 1.0368299 | AT24: 1.605774 | AU24: 2.1257496 | AV24: 1.2455286 | AW24: 0.89822838 | AX24: 1.4357023 | AY24: 0.45731243 | AZ24: 0.96851789 | BA24: 0.90775562 | BB24: 0.65776763 | BC24: 0.18814543 | BD24: 0.96875629 | BE24: 1.210068 | BF24: 1.0477057 | BG24: 0.74885109 | BH24: 1.1182645 | BI24: 1.1834579 | BJ24: 0.98110748 | BK24: 0.93785552 | BL24: 1.0661619 | BM24: 1.3164328 | BN24: 1.0594485 | BO24: 0.92228995 | BP24: 1.0423722 | BQ24: 1.1219052 | BR24: 1.2011504 | BS24: 1.5040327 | BT24: 0.98258299 | BU24: 1.0047792 | BV24: 1.1189829 | BW24: 0.90307576 | BX24: 1.0568539 | BY24: 0.87332078 | BZ24: 1.0184969 | CA24: 0.99699963 | CB24: 0.95397253
A25: 357 | B25: 1.449371 | C25: 1.1825408 | D25: 1.0942029 | E25: 0.74848532 | F25: 0.77292539 | G25: 0.92153029 | H25: 0.67294971 | I25: 0.71934076 | J25: 0.91567847 | K25: 1.2877652 | L25: 0.79113043 | M25: 0.96841055 | N25: 0.79955658 | O25: 0.96296545 | P25: 0.77772423 | Q25: 0.98794338 | R25: 0.9166996 | S25: 0.94782176 | T25: 0.91040796 | U25: 0.73744948 | V25: 1.6138165 | W25: 1.4142445 | X25: 1.6005998 | Y25: 1.5231825 | Z25: 0.73099512 | AA25: 1.2811896 | AB25: 1.4139505 | AC25: 0.86083658 | AD25: 1.4434613 | AE25: 1.0713547 | AF25: 1.0113366 | AG25: 0.47217275 | AH25: 0.70705531 | AI25: 0.8716324 | AJ25: 0.92197327 | AK25: 0.77235535 | AL25: 0.48878207 | AM25: 0.38882188 | AN25: 0.89435773 | AO25: 0.84952662 | AP25: 0.76178781 | AQ25: 0.4592826 | AR25: 1.1360442 | AS25: 0.94141006 | AT25: 1.2831243 | AU25: 2.0138681 | AV25: 0.87926185 | AW25: 0.86076739 | AX25: 1.4035759 | AY25: 0.45553127 | AZ25: 0.99366113 | BA25: 0.92916036 | BB25: 0.67758958 | BC25: 0.6913778 | BD25: 0.96875629 | BE25: 1.0405907 | BF25: 1.0311681 | BG25: 0.59243311 | BH25: 1.1441318 | BI25: 1.2625749 | BJ25: 0.96550635 | BK25: 0.92783958 | BL25: 1.0962271 | BM25: 1.2778033 | BN25: 1.0812519 | BO25: 0.94254522 | BP25: 0.85749407 | BQ25: 1.2471015 | BR25: 1.2206229 | BS25: 1.4921806 | BT25: 1.008348 | BU25: 0.99281854 | BV25: 1.062997 | BW25: 0.85053833 | BX25: 1.0265222 | BY25: 0.68205716 | BZ25: 0.89627731 | CA25: 1.0272432 | CB25: 0.94964939
A26: 358 | B26: 1.4184635 | C26: 1.2020123 | D26: 1.1186585 | E26: 0.76936334 | F26: 0.90028242 | G26: 0.89155723 | H26: 0.23761369 | I26: 1.0188214 | J26: 1.0187997 | K26: 1.3589124 | L26: 0.78352749 | M26: 0.9945838 | N26: 0.77772066 | O26: 0.94968556 | P26: 0.79459819 | Q26: 0.9759513 | R26: 0.89730369 | S26: 0.93424846 | T26: 0.85978973 | U26: 0.69502611 | V26: 1.5962603 | W26: 1.4112204 | X26: 1.5637681 | Y26: 1.0689396 | Z26: 0.71206601 | AA26: 1.2677034 | AB26: 1.3357825 | AC26: 0.88069402 | AD26: 1.4836433 | AE26: 1.0372812 | AF26: 1.0052146 | AG26: 0.34445389 | AH26: 0.61333664 | AI26: 0.90234099 | AJ26: 0.93420103 | AK26: 0.79986192 | AL26: 0.43373904 | AM26: 0.34785258 | AN26: 1.2454876 | AO26: 0.86897711 | AP26: 0.77874336 | AQ26: 0.62904884 | AR26: 1.1207382 | AS26: 0.92763812 | AT26: 1.1386171 | AU26: 1.4446842 | AV26: 1.0064019 | AW26: 0.81314039 | AX26: 1.3532156 | AY26: 0.42564121 | AZ26: 0.96650643 | BA26: 0.92818741 | BB26: 0.71319968 | BC26: 0.22214762 | BD26: 0.91428807 | BE26: 0.7372263 | BF26: 0.99712007 | BG26: 0.25808967 | BH26: 1.0774737 | BI26: 1.340593 | BJ26: 0.95275412 | BK26: 0.90348266 | BL26: 1.1387355 | BM26: 1.3077222 | BN26: 1.0951268 | BO26: 0.98170541 | BP26: 0.75532456 | BQ26: 1.1875421 | BR26: 1.2421452 | BS26: 1.4637355 | BT26: 1.0142037 | BU26: 0.97412999 | BV26: 1.0287424 | BW26: 0.84769847 | BX26: 0.9970825 | BY26: 0.50455795 | BZ26: 1.0481259 | CA26: 1.0291242 | CB26: 0.94100312
A27: 359 | B27: 1.3767854 | C27: 1.2054893 | D27: 1.1628477 | E27: 0.63423157 | F27: 0.80849753 | G27: 0.92266135 | H27: 0.65387124 | I27: 0.54023959 | J27: 0.95005222 | K27: 1.3751747 | L27: 0.79283108 | M27: 0.97588862 | N27: 0.78046689 | O27: 0.92959166 | P27: 0.79209584 | Q27: 0.96651073 | R27: 0.89415479 | S27: 0.93222226 | T27: 0.89833641 | U27: 0.6719832 | V27: 1.5811636 | W27: 1.3991243 | X27: 1.5469307 | Y27: 1.0553801 | Z27: 0.73895363 | AA27: 1.3621069 | AB27: 1.3377614 | AC27: 0.88715046 | AD27: 1.4508796 | AE27: 1.0450797 | AF27: 1.010273 | AG27: 0.4050881 | AH27: 0.71955113 | AI27: 0.90504334 | AJ27: 0.93691831 | AK27: 0.78538478 | AL27: 0.15034609 | AM27: 0.32021762 | AN27: 0.72115465 | AO27: 0.91732088 | AP27: 0.78217825 | AQ27: 0.49150452 | AR27: 1.1496495 | AS27: 0.89911054 | AT27: 1.04394 | AU27: 1.0101927 | AV27: 0.80423446 | AW27: 0.84127096 | AX27: 1.33585 | AY27: 0.45107838 | AZ27: 0.97455226 | BA27: 0.93888979 | BB27: 0.69255363 | BC27: 0.86365555 | BD27: 0.94444012 | BE27: 0.99991613 | BF27: 1.0272769 | BG27: 0.90917952 | BH27: 1.0824482 | BI27: 1.4438846 | BJ27: 0.99413103 | BK27: 0.9410424 | BL27: 1.0740019 | BM27: 1.2956032 | BN27: 1.0594485 | BO27: 0.63736582 | BP27: 0.68477895 | BQ27: 0.88974493 | BR27: 1.0156485 | BS27: 1.5087736 | BT27: 1.1254616 | BU27: 0.96275074 | BV27: 1.0176925 | BW27: 0.78948132 | BX27: 0.95217959 | BY27: 0.52140394 | BZ27: 0.71294786 | CA27: 0.98927785 | CB27: 0.91506429
A28: 360 | B28: 1.3496243 | C28: 1.2242653 | D28: 1.1264944 | E28: 0.62190203 | F28: 0.7101252 | G28: 0.92096476 | H28: 1.0527847 | I28: 0.51675091 | J28: 0.81446688 | K28: 1.3223224 | L28: 0.80993769 | M28: 0.94448071 | N28: 0.74168468 | O28: 0.89771 | P28: 0.78144394 | Q28: 0.96702103 | R28: 0.88882845 | S28: 0.93625286 | T28: 0.90114853 | U28: 0.67892659 | V28: 1.4859189 | W28: 1.4041643 | X28: 1.5700821 | Y28: 1.2147041 | Z28: 0.74105379 | AA28: 1.3396299 | AB28: 1.3605192 | AC28: 0.86352122 | AD28: 1.3692792 | AE28: 1.0431201 | AF28: 0.97699152 | AG28: 0.41798899 | AH28: 0.72163377 | AI28: 0.83453644 | AJ28: 0.95376545 | AK28: 0.7665645 | AL28: 0.12392544 | AM28: 0.22455816 | AN28: 0.75579526 | AO28: 0.87954979 | AP28: 0.78216142 | AQ28: 0.431389 | AR28: 1.1607038 | AS28: 0.86271329 | AT28: 1.3790472 | AU28: 1.6032736 | AV28: 0.92287383 | AW28: 0.84419542 | AX28: 1.3462694 | AY28: 0.52371624 | AZ28: 0.96952362 | BA28: 0.94472744 | BB28: 0.63655772 | BC28: 0.074804811 | BD28: 0.9045616 | BE28: 0.61011832 | BF28: 0.98155527 | BG28: 0.22680607 | BH28: 1.0754839 | BI28: 1.1933475 | BJ28: 0.98680528 | BK28: 0.91258805 | BL28: 1.0493312 | BM28: 1.2967393 | BN28: 1.0594485 | BO28: 0.45101734 | BP28: 0.67991374 | BQ28: 0.73416112 | BR28: 1.1837275 | BS28: 1.3309919 | BT28: 0.92285506 | BU28: 0.98509394 | BV28: 1.0490005 | BW28: 1.0635279 | BX28: 0.96942707 | BY28: 0.68390611 | BZ28: 0.59443185 | CA28: 1.0068498 | CB28: 0.93812103
A29: 361 | B29: 1.401605 | C29: 1.1981875 | D29: 1.1308609 | E29: 0.64491718 | F29: 0.61219204 | G29: 0.90145399 | H29: 0.97473644 | I29: 0.72668097 | J29: 0.8803499 | K29: 1.3599288 | L29: 0.82979536 | M29: 0.94597632 | N29: 0.75809512 | O29: 0.87930717 | P29: 0.78414918 | Q29: 0.97059314 | R29: 0.88460758 | S29: 0.9760795 | T29: 0.90214306 | U29: 0.6947972 | V29: 1.4744692 | W29: 1.4172685 | X29: 1.5079944 | Y29: 0.96498355 | Z29: 0.72248393 | AA29: 1.1643092 | AB29: 1.2942248 | AC29: 0.84217725 | AD29: 1.3253881 | AE29: 1.0364414 | AF29: 0.95081771 | AG29: 0.46830248 | AH29: 0.60604741 | AI29: 0.83674745 | AJ29: 0.92197327 | AK29: 0.74750293 | AL29: 0.23369696 | AM29: 0.30630352 | AN29: 0.74477325 | AO29: 0.86978419 | AP29: 0.79344267 | AQ29: 0.22651529 | AR29: 1.1564521 | AS29: 0.8430391 | AT29: 1.0912786 | AU29: 1.5446172 | AV29: 0.850064 | AW29: 0.76453858 | AX29: 1.3454011 | AY29: 0.54291936 | AZ29: 0.96047205 | BA29: 0.92526859 | BB29: 0.64315057 | BC29: -0.108807 | BD29: 0.92693248 | BE29: 0.87111338 | BF29: 1.0010113 | BG29: 0.95414969 | BH29: 0.97997379 | BI29: 1.1054398 | BJ29: 0.97201813 | BK29: 0.9260185 | BL29: 1.0659461 | BM29: 1.3046925 | BN29: 1.0356629 | BO29: 0.50233069 | BP29: 0.69450938 | BQ29: 0.78156556 | BR29: 1.1724539 | BS29: 1.1958779 | BT29: 0.82682192 | BU29: 0.99971253 | BV29: 1.0806767 | BW29: 0.99111145 | BX29: 1.0057062 | BY29: 0.84250495 | BZ29: 0.72961417 | CA29: 1.017789 | CB29: 0.9486887
... A418: 750 | B418: -0.029502543 | C418: -0.0013908155 | D418: -0.0045187723 | E418: -0.10619844 | F418: -0.093102377 | G418: -0.017531414 | H418: -0.53419719 | I418: -0.5578561 | J418: -0.25589346 | K418: -0.031508067 | L418: -0.0064274814 | M418: -0.01420834 | N418: -0.0084061616 | O418: -0.0029842429 | P418: -0.0088934941 | Q418: -0.01148178 | R418: -0.0039193807 | S418: -0.0098041511 | T418: -0.017798687 | U418: -0.05837029 | V418: -0.11195279 | W418: -0.017136248 | X418: -0.039988686 | Y418: 0.025989018 | Z418: 0.0038963562 | AA418: 0.074174136 | AB418: -0.020778839 | AC418: -0.00093185743 | AD418: -0.20523733 | AE418: 0.0090382681 | AF418: -0.011154352 | AG418: 0.25414763 | AH418: 0.11037977 | AI418: -0.019162155 | AJ418: -0.014945043 | AK418: -0.0084449976 | AL418: 0.027049715 | AM418: -0.0096625716 | AN418: 0.15745735 | AO418: -0.0066987184 | AP418: -0.0019868479 | AQ418: -0.34482264 | AR418: -0.070577593 | AS418: -0.062957412 | AT418: 0.0099660142 | AU418: 0.54311436 | AV418: -0.022175583 | AW418: -0.10528072 | AX418: -0.02214116 | AY418: -0.021652207 | AZ418: -0.024137517 | BA418: -0.013621199 | BB418: -0.029581109 | BC418: -0.8727228 | BD418: -0.02820676 | BE418: -0.29828007 | BF418: -0.0087552006 | BG418: 0.10753736 | BH418: -0.086556061 | BI418: -0.16153046 | BJ418: -0.021570256 | BK418: 0.0047803315 | BL418: -0.017909622 | BM418: -0.022344516 | BN418: -0.010901715 | BO418: -0.6076581 | BP418: -0.34178132 | BQ418: -0.32696911 | BR418: -0.32283478 | BS418: -0.29511753 | BT418: -0.2646767 | BU418: 0.01279127 | BV418: -0.0011049864 | BW418: -0.18033117 | BX418: 0.011894811 | BY418: 0.014586162 | BZ418: -0.41665784 | CA418: -0.0056923323 | CB418: -0.016812205

Sheet T-Type
A1: wl | B1: 2019Oct31-1.XLS | C1: 2019Oct31-13.XLS | D1: 2019Oct31-14.XLS | E1: 2019Oct31-166.XLS | F1: 2019Oct31-167.XLS | G1: 2019Oct31-168.XLS | H1: 2019Oct31-180.XLS | I1: 2019Oct31-33.XLS | J1: 2019Oct31-43.XLS | K1: 2019Oct31-57.XLS | L1: 2019Oct31-61.XLS | M1: 2019Oct31-69.XLS | N1: 2019Oct31-85.XLS | O1: 2019Oct31-87.XLS | P1: 2019Oct31-44 | Q1: 2019Oct31-62 | R1: 2019Oct31-66
A2: 350 | B2: 0.027 | C2: 0.034 | D2: 0.023 | E2: -0.001 | F2: 0.001 | G2: 0.068 | H2: -0.007 | I2: -0.018 | J2: -0.048 | K2: 0.046 | L2: 0.004 | M2: 0.06 | N2: 0.024 | O2: 0.015 | P2: -0.001 | Q2: 0.016 | R2: 0.027
A3: 351 | B3: 0.025 | C3: 0.036 | D3: 0.014 | E3: -0.011 | F3: 0.003 | G3: 0.061 | H3: -0.022 | I3: -0.009 | J3: -0.025 | K3: 0.053 | L3: -0.004 | M3: 0.028 | N3: 0.037 | O3: 0.008 | P3: 0.025 | Q3: 0.005 | R3: 0.019
A4: 352 | B4: 0.02 | C4: 0.045 | D4: 0.016 | E4: 0.008 | F4: 0.014 | G4: 0.06 | H4: -0.01 | I4: -0.003 | J4: -0.028 | K4: 0.053 | L4: -0.006 | M4: 0.032 | N4: 0.032 | O4: 0.006 | P4: 0.019 | Q4: -0.002 | R4: 0.01
A5: 353 | B5: 0.02 | C5: 0.037 | D5: 0.026 | E5: 0.01 | F5: 0.016 | G5: 0.065 | H5: -0.01 | I5: 0.001 | J5: -0.03 | K5: 0.034 | L5: -0.005 | M5: 0.031 | N5: 0.031 | O5: 0.021 | P5: 0.015 | Q5: 0.013 | R5: 0.007
A6: 354 | B6: 0.016 | C6: 0.035 | D6: 0.032 | E6: -0.007 | F6: 0.007 | G6: 0.077 | H6: -0.026 | I6: 0.004 | J6: -0.024 | K6: 0.036 | L6: -0.004 | M6: 0.03 | N6: 0.036 | O6: 0.024 | P6: 0.018 | Q6: 0.003 | R6: 0.002
A7: 355 | B7: 0.009 | C7: 0.04 | D7: 0.029 | E7: -0.005 | F7: 0.005 | G7: 0.06 | H7: -0.033 | I7: -0.004 | J7: -0.032 | K7: 0.037 | L7: 0 | M7: 0.036 | N7: 0.034 | O7: 0.018 | P7: 0.016 | Q7: 0.005 | R7: 0.003
A8: 356 | B8: 0.012 | C8: 0.026 | D8: 0.024 | E8: -0.008 | F8: -0.005 | G8: 0.054 | H8: -0.031 | I8: -0.01 | J8: -0.025 | K8: 0.037 | L8: -0.001 | M8: 0.043 | N8: 0.032 | O8: 0.013 | P8: 0.025 | Q8: 0.012 | R8: 0.014
A9: 357 | B9: 0.01 | C9: 0.03 | D9: 0.015 | E9: -0.011 | F9: 0.002 | G9: 0.047 | H9: -0.037 | I9: -0.009 | J9: -0.011 | K9: 0.037 | L9: -0.002 | M9: 0.043 | N9: 0.029 | O9: 0.016 | P9: 0.02 | Q9: 0.018 | R9: 0.012
A10: 358 | B10: 0.007 | C10: 0.026 | D10: 0.019 | E10: -0.01 | F10: -0.006 | G10: 0.039 | H10: -0.027 | I10: -0.009 | J10: -0.017 | K10: 0.036 | L10: 0 | M10: 0.041 | N10: 0.029 | O10: 0.015 | P10: 0.026 | Q10: 0.013 | R10: 0.008
A11: 359 | B11: 0.007 | C11: 0.031 | D11: 0.015 | E11: -0.007 | F11: -0.005 | G11: 0.036 | H11: -0.02 | I11: -0.001 | J11: -0.038 | K11: 0.04 | L11: -0.002 | M11: 0.04 | N11: 0.009 | O11: 0.007 | P11: 0.016 | Q11: 0.02 | R11: 0.016
